[2023-12-22T03:53:00.035+0000] {taskinstance.py:1957} INFO - Dependencies all met for dep_context=non-requeueable deps ti=<TaskInstance: out_first_dag_V3.third_task manual__2023-12-22T03:52:54.042752+00:00 [queued]>
[2023-12-22T03:53:00.123+0000] {taskinstance.py:1957} INFO - Dependencies all met for dep_context=requeueable deps ti=<TaskInstance: out_first_dag_V3.third_task manual__2023-12-22T03:52:54.042752+00:00 [queued]>
[2023-12-22T03:53:00.124+0000] {taskinstance.py:2171} INFO - Starting attempt 1 of 1
[2023-12-22T03:53:00.177+0000] {taskinstance.py:2192} INFO - Executing <Task(BashOperator): third_task> on 2023-12-22 03:52:54.042752+00:00
[2023-12-22T03:53:00.197+0000] {standard_task_runner.py:60} INFO - Started process 675 to run task
[2023-12-22T03:53:00.206+0000] {standard_task_runner.py:87} INFO - Running: ['***', 'tasks', 'run', 'out_first_dag_V3', 'third_task', 'manual__2023-12-22T03:52:54.042752+00:00', '--job-id', '17', '--raw', '--subdir', 'DAGS_FOLDER/first_dag.py', '--cfg-path', '/tmp/tmpus8eevn4']
[2023-12-22T03:53:00.227+0000] {standard_task_runner.py:88} INFO - Job 17: Subtask third_task
[2023-12-22T03:53:00.449+0000] {task_command.py:423} INFO - Running <TaskInstance: out_first_dag_V3.third_task manual__2023-12-22T03:52:54.042752+00:00 [running]> on host c00ebe49daba
[2023-12-22T03:53:00.761+0000] {taskinstance.py:2481} INFO - Exporting env vars: AIRFLOW_CTX_DAG_OWNER='***' AIRFLOW_CTX_DAG_ID='out_first_dag_V3' AIRFLOW_CTX_TASK_ID='third_task' AIRFLOW_CTX_EXECUTION_DATE='2023-12-22T03:52:54.042752+00:00' AIRFLOW_CTX_TRY_NUMBER='1' AIRFLOW_CTX_DAG_RUN_ID='manual__2023-12-22T03:52:54.042752+00:00'
[2023-12-22T03:53:00.768+0000] {subprocess.py:63} INFO - Tmp dir root location: /tmp
[2023-12-22T03:53:00.769+0000] {subprocess.py:75} INFO - Running command: ['/usr/bin/bash', '-c', "echo this is the third task, it'll be running after task1 & at the same time as task2"]
[2023-12-22T03:53:00.828+0000] {subprocess.py:86} INFO - Output:
[2023-12-22T03:53:00.834+0000] {subprocess.py:93} INFO - /usr/bin/bash: -c: line 1: unexpected EOF while looking for matching `''
[2023-12-22T03:53:00.838+0000] {subprocess.py:97} INFO - Command exited with return code 2
[2023-12-22T03:53:00.913+0000] {taskinstance.py:2699} ERROR - Task failed with exception
Traceback (most recent call last):
  File "/home/airflow/.local/lib/python3.8/site-packages/airflow/models/taskinstance.py", line 433, in _execute_task
    result = execute_callable(context=context, **execute_callable_kwargs)
  File "/home/airflow/.local/lib/python3.8/site-packages/airflow/operators/bash.py", line 212, in execute
    raise AirflowException(
airflow.exceptions.AirflowException: Bash command failed. The command returned a non-zero exit code 2.
[2023-12-22T03:53:00.946+0000] {taskinstance.py:1138} INFO - Marking task as FAILED. dag_id=out_first_dag_V3, task_id=third_task, execution_date=20231222T035254, start_date=20231222T035300, end_date=20231222T035300
[2023-12-22T03:53:00.985+0000] {standard_task_runner.py:107} ERROR - Failed to execute job 17 for task third_task (Bash command failed. The command returned a non-zero exit code 2.; 675)
[2023-12-22T03:53:01.044+0000] {local_task_job_runner.py:234} INFO - Task exited with return code 1
[2023-12-22T03:53:01.087+0000] {taskinstance.py:3281} INFO - 0 downstream tasks scheduled from follow-on schedule check
