[2023-12-22T03:53:48.052+0000] {taskinstance.py:1957} INFO - Dependencies all met for dep_context=non-requeueable deps ti=<TaskInstance: out_first_dag_V3.third_task manual__2023-12-22T03:53:44.469729+00:00 [queued]>
[2023-12-22T03:53:48.068+0000] {taskinstance.py:1957} INFO - Dependencies all met for dep_context=requeueable deps ti=<TaskInstance: out_first_dag_V3.third_task manual__2023-12-22T03:53:44.469729+00:00 [queued]>
[2023-12-22T03:53:48.070+0000] {taskinstance.py:2171} INFO - Starting attempt 1 of 1
[2023-12-22T03:53:48.095+0000] {taskinstance.py:2192} INFO - Executing <Task(BashOperator): third_task> on 2023-12-22 03:53:44.469729+00:00
[2023-12-22T03:53:48.104+0000] {standard_task_runner.py:60} INFO - Started process 701 to run task
[2023-12-22T03:53:48.112+0000] {standard_task_runner.py:87} INFO - Running: ['***', 'tasks', 'run', 'out_first_dag_V3', 'third_task', 'manual__2023-12-22T03:53:44.469729+00:00', '--job-id', '20', '--raw', '--subdir', 'DAGS_FOLDER/first_dag.py', '--cfg-path', '/tmp/tmp36jgbtds']
[2023-12-22T03:53:48.115+0000] {standard_task_runner.py:88} INFO - Job 20: Subtask third_task
[2023-12-22T03:53:48.191+0000] {task_command.py:423} INFO - Running <TaskInstance: out_first_dag_V3.third_task manual__2023-12-22T03:53:44.469729+00:00 [running]> on host c00ebe49daba
[2023-12-22T03:53:48.342+0000] {taskinstance.py:2481} INFO - Exporting env vars: AIRFLOW_CTX_DAG_OWNER='***' AIRFLOW_CTX_DAG_ID='out_first_dag_V3' AIRFLOW_CTX_TASK_ID='third_task' AIRFLOW_CTX_EXECUTION_DATE='2023-12-22T03:53:44.469729+00:00' AIRFLOW_CTX_TRY_NUMBER='1' AIRFLOW_CTX_DAG_RUN_ID='manual__2023-12-22T03:53:44.469729+00:00'
[2023-12-22T03:53:48.344+0000] {subprocess.py:63} INFO - Tmp dir root location: /tmp
[2023-12-22T03:53:48.345+0000] {subprocess.py:75} INFO - Running command: ['/usr/bin/bash', '-c', "echo this is the third task, it'll be running after task1 & at the same time as task2"]
[2023-12-22T03:53:48.365+0000] {subprocess.py:86} INFO - Output:
[2023-12-22T03:53:48.369+0000] {subprocess.py:93} INFO - /usr/bin/bash: -c: line 1: unexpected EOF while looking for matching `''
[2023-12-22T03:53:48.370+0000] {subprocess.py:97} INFO - Command exited with return code 2
[2023-12-22T03:53:48.396+0000] {taskinstance.py:2699} ERROR - Task failed with exception
Traceback (most recent call last):
  File "/home/airflow/.local/lib/python3.8/site-packages/airflow/models/taskinstance.py", line 433, in _execute_task
    result = execute_callable(context=context, **execute_callable_kwargs)
  File "/home/airflow/.local/lib/python3.8/site-packages/airflow/operators/bash.py", line 212, in execute
    raise AirflowException(
airflow.exceptions.AirflowException: Bash command failed. The command returned a non-zero exit code 2.
[2023-12-22T03:53:48.401+0000] {taskinstance.py:1138} INFO - Marking task as FAILED. dag_id=out_first_dag_V3, task_id=third_task, execution_date=20231222T035344, start_date=20231222T035348, end_date=20231222T035348
[2023-12-22T03:53:48.432+0000] {standard_task_runner.py:107} ERROR - Failed to execute job 20 for task third_task (Bash command failed. The command returned a non-zero exit code 2.; 701)
[2023-12-22T03:53:48.489+0000] {local_task_job_runner.py:234} INFO - Task exited with return code 1
[2023-12-22T03:53:48.515+0000] {taskinstance.py:3281} INFO - 0 downstream tasks scheduled from follow-on schedule check
