[2023-12-22T05:44:22.952+0000] {taskinstance.py:1957} INFO - Dependencies all met for dep_context=non-requeueable deps ti=<TaskInstance: dag_with_python_operator_v5.greet scheduled__2023-12-21T00:00:00+00:00 [queued]>
[2023-12-22T05:44:22.969+0000] {taskinstance.py:1957} INFO - Dependencies all met for dep_context=requeueable deps ti=<TaskInstance: dag_with_python_operator_v5.greet scheduled__2023-12-21T00:00:00+00:00 [queued]>
[2023-12-22T05:44:22.969+0000] {taskinstance.py:2171} INFO - Starting attempt 1 of 6
[2023-12-22T05:44:22.994+0000] {taskinstance.py:2192} INFO - Executing <Task(PythonOperator): greet> on 2023-12-21 00:00:00+00:00
[2023-12-22T05:44:23.003+0000] {standard_task_runner.py:60} INFO - Started process 2068 to run task
[2023-12-22T05:44:23.010+0000] {standard_task_runner.py:87} INFO - Running: ['***', 'tasks', 'run', 'dag_with_python_operator_v5', 'greet', 'scheduled__2023-12-21T00:00:00+00:00', '--job-id', '57', '--raw', '--subdir', 'DAGS_FOLDER/second_dag_with_python_operator.py', '--cfg-path', '/tmp/tmpw1attjm3']
[2023-12-22T05:44:23.012+0000] {standard_task_runner.py:88} INFO - Job 57: Subtask greet
[2023-12-22T05:44:23.094+0000] {task_command.py:423} INFO - Running <TaskInstance: dag_with_python_operator_v5.greet scheduled__2023-12-21T00:00:00+00:00 [running]> on host c00ebe49daba
[2023-12-22T05:44:23.218+0000] {taskinstance.py:2481} INFO - Exporting env vars: AIRFLOW_CTX_DAG_OWNER='Kh. Tanjim Ashraf' AIRFLOW_CTX_DAG_ID='dag_with_python_operator_v5' AIRFLOW_CTX_TASK_ID='greet' AIRFLOW_CTX_EXECUTION_DATE='2023-12-21T00:00:00+00:00' AIRFLOW_CTX_TRY_NUMBER='1' AIRFLOW_CTX_DAG_RUN_ID='scheduled__2023-12-21T00:00:00+00:00'
[2023-12-22T05:44:23.220+0000] {taskinstance.py:2699} ERROR - Task failed with exception
Traceback (most recent call last):
  File "/home/airflow/.local/lib/python3.8/site-packages/airflow/models/taskinstance.py", line 433, in _execute_task
    result = execute_callable(context=context, **execute_callable_kwargs)
  File "/home/airflow/.local/lib/python3.8/site-packages/airflow/operators/python.py", line 199, in execute
    return_value = self.execute_callable()
  File "/home/airflow/.local/lib/python3.8/site-packages/airflow/operators/python.py", line 216, in execute_callable
    return self.python_callable(*self.op_args, **self.op_kwargs)
  File "/opt/airflow/dags/second_dag_with_python_operator.py", line 30, in greet
    first_name = ti.xcom_pull(task_id='get_name', key='first_name')
  File "/home/airflow/.local/lib/python3.8/site-packages/airflow/utils/session.py", line 79, in wrapper
    return func(*args, session=session, **kwargs)
TypeError: xcom_pull() got an unexpected keyword argument 'task_id'
[2023-12-22T05:44:23.234+0000] {taskinstance.py:1138} INFO - Marking task as UP_FOR_RETRY. dag_id=dag_with_python_operator_v5, task_id=greet, execution_date=20231221T000000, start_date=20231222T054422, end_date=20231222T054423
[2023-12-22T05:44:23.252+0000] {standard_task_runner.py:107} ERROR - Failed to execute job 57 for task greet (xcom_pull() got an unexpected keyword argument 'task_id'; 2068)
[2023-12-22T05:44:23.302+0000] {local_task_job_runner.py:234} INFO - Task exited with return code 1
[2023-12-22T05:44:23.326+0000] {taskinstance.py:3281} INFO - 0 downstream tasks scheduled from follow-on schedule check
