[2023-12-22T05:29:48.235+0000] {taskinstance.py:1957} INFO - Dependencies all met for dep_context=non-requeueable deps ti=<TaskInstance: dag_with_python_operator_v4.greet scheduled__2023-12-21T00:00:00+00:00 [queued]>
[2023-12-22T05:29:48.250+0000] {taskinstance.py:1957} INFO - Dependencies all met for dep_context=requeueable deps ti=<TaskInstance: dag_with_python_operator_v4.greet scheduled__2023-12-21T00:00:00+00:00 [queued]>
[2023-12-22T05:29:48.251+0000] {taskinstance.py:2171} INFO - Starting attempt 1 of 6
[2023-12-22T05:29:48.278+0000] {taskinstance.py:2192} INFO - Executing <Task(PythonOperator): greet> on 2023-12-21 00:00:00+00:00
[2023-12-22T05:29:48.287+0000] {standard_task_runner.py:60} INFO - Started process 1843 to run task
[2023-12-22T05:29:48.295+0000] {standard_task_runner.py:87} INFO - Running: ['***', 'tasks', 'run', 'dag_with_python_operator_v4', 'greet', 'scheduled__2023-12-21T00:00:00+00:00', '--job-id', '49', '--raw', '--subdir', 'DAGS_FOLDER/second_dag_with_python_operator.py', '--cfg-path', '/tmp/tmpxaz1xv2n']
[2023-12-22T05:29:48.297+0000] {standard_task_runner.py:88} INFO - Job 49: Subtask greet
[2023-12-22T05:29:48.385+0000] {task_command.py:423} INFO - Running <TaskInstance: dag_with_python_operator_v4.greet scheduled__2023-12-21T00:00:00+00:00 [running]> on host c00ebe49daba
[2023-12-22T05:29:48.502+0000] {taskinstance.py:2481} INFO - Exporting env vars: AIRFLOW_CTX_DAG_OWNER='Kh. Tanjim Ashraf' AIRFLOW_CTX_DAG_ID='dag_with_python_operator_v4' AIRFLOW_CTX_TASK_ID='greet' AIRFLOW_CTX_EXECUTION_DATE='2023-12-21T00:00:00+00:00' AIRFLOW_CTX_TRY_NUMBER='1' AIRFLOW_CTX_DAG_RUN_ID='scheduled__2023-12-21T00:00:00+00:00'
[2023-12-22T05:29:48.503+0000] {taskinstance.py:2699} ERROR - Task failed with exception
Traceback (most recent call last):
  File "/home/airflow/.local/lib/python3.8/site-packages/airflow/models/taskinstance.py", line 433, in _execute_task
    result = execute_callable(context=context, **execute_callable_kwargs)
  File "/home/airflow/.local/lib/python3.8/site-packages/airflow/operators/python.py", line 199, in execute
    return_value = self.execute_callable()
  File "/home/airflow/.local/lib/python3.8/site-packages/airflow/operators/python.py", line 216, in execute_callable
    return self.python_callable(*self.op_args, **self.op_kwargs)
  File "/opt/airflow/dags/second_dag_with_python_operator.py", line 16, in greet
    name = ti.xcoms_pull(task_ids='get_name')
AttributeError: 'TaskInstance' object has no attribute 'xcoms_pull'
[2023-12-22T05:29:48.519+0000] {taskinstance.py:1138} INFO - Marking task as UP_FOR_RETRY. dag_id=dag_with_python_operator_v4, task_id=greet, execution_date=20231221T000000, start_date=20231222T052948, end_date=20231222T052948
[2023-12-22T05:29:48.536+0000] {standard_task_runner.py:107} ERROR - Failed to execute job 49 for task greet ('TaskInstance' object has no attribute 'xcoms_pull'; 1843)
[2023-12-22T05:29:48.549+0000] {local_task_job_runner.py:234} INFO - Task exited with return code 1
[2023-12-22T05:29:48.575+0000] {taskinstance.py:3281} INFO - 0 downstream tasks scheduled from follow-on schedule check
