[2023-12-21T19:47:45.784+0000] {processor.py:161} INFO - Started process (PID=91) to work on /opt/airflow/dags/first_dag.py
[2023-12-21T19:47:45.786+0000] {processor.py:830} INFO - Processing file /opt/airflow/dags/first_dag.py for tasks to queue
[2023-12-21T19:47:45.793+0000] {logging_mixin.py:188} INFO - [2023-12-21T19:47:45.792+0000] {dagbag.py:538} INFO - Filling up the DagBag from /opt/airflow/dags/first_dag.py
[2023-12-21T19:47:45.803+0000] {logging_mixin.py:188} INFO - [2023-12-21T19:47:45.800+0000] {dagbag.py:348} ERROR - Failed to import: /opt/airflow/dags/first_dag.py
Traceback (most recent call last):
  File "/home/airflow/.local/lib/python3.8/site-packages/airflow/models/dagbag.py", line 344, in parse
    loader.exec_module(new_module)
  File "<frozen importlib._bootstrap_external>", line 839, in exec_module
  File "<frozen importlib._bootstrap_external>", line 976, in get_code
  File "<frozen importlib._bootstrap_external>", line 906, in source_to_code
  File "<frozen importlib._bootstrap>", line 219, in _call_with_frames_removed
  File "/opt/airflow/dags/first_dag.py", line 5
    dag_id-="our first dag",
          ^
SyntaxError: invalid syntax
[2023-12-21T19:47:45.804+0000] {processor.py:842} WARNING - No viable dags retrieved from /opt/airflow/dags/first_dag.py
[2023-12-21T19:47:45.841+0000] {processor.py:183} INFO - Processing /opt/airflow/dags/first_dag.py took 0.070 seconds
[2023-12-21T19:47:46.829+0000] {processor.py:161} INFO - Started process (PID=92) to work on /opt/airflow/dags/first_dag.py
[2023-12-21T19:47:46.831+0000] {processor.py:830} INFO - Processing file /opt/airflow/dags/first_dag.py for tasks to queue
[2023-12-21T19:47:46.835+0000] {logging_mixin.py:188} INFO - [2023-12-21T19:47:46.834+0000] {dagbag.py:538} INFO - Filling up the DagBag from /opt/airflow/dags/first_dag.py
[2023-12-21T19:47:46.839+0000] {logging_mixin.py:188} INFO - [2023-12-21T19:47:46.838+0000] {dagbag.py:348} ERROR - Failed to import: /opt/airflow/dags/first_dag.py
Traceback (most recent call last):
  File "/home/airflow/.local/lib/python3.8/site-packages/airflow/models/dagbag.py", line 344, in parse
    loader.exec_module(new_module)
  File "<frozen importlib._bootstrap_external>", line 839, in exec_module
  File "<frozen importlib._bootstrap_external>", line 976, in get_code
  File "<frozen importlib._bootstrap_external>", line 906, in source_to_code
  File "<frozen importlib._bootstrap>", line 219, in _call_with_frames_removed
  File "/opt/airflow/dags/first_dag.py", line 5
    dag_id-="our first dag",
          ^
SyntaxError: invalid syntax
[2023-12-21T19:47:46.840+0000] {processor.py:842} WARNING - No viable dags retrieved from /opt/airflow/dags/first_dag.py
[2023-12-21T19:47:46.871+0000] {processor.py:183} INFO - Processing /opt/airflow/dags/first_dag.py took 0.050 seconds
[2023-12-21T19:47:54.932+0000] {processor.py:161} INFO - Started process (PID=99) to work on /opt/airflow/dags/first_dag.py
[2023-12-21T19:47:54.940+0000] {processor.py:830} INFO - Processing file /opt/airflow/dags/first_dag.py for tasks to queue
[2023-12-21T19:47:54.944+0000] {logging_mixin.py:188} INFO - [2023-12-21T19:47:54.943+0000] {dagbag.py:538} INFO - Filling up the DagBag from /opt/airflow/dags/first_dag.py
[2023-12-21T19:47:54.948+0000] {logging_mixin.py:188} INFO - [2023-12-21T19:47:54.947+0000] {dagbag.py:348} ERROR - Failed to import: /opt/airflow/dags/first_dag.py
Traceback (most recent call last):
  File "/home/airflow/.local/lib/python3.8/site-packages/airflow/models/dagbag.py", line 344, in parse
    loader.exec_module(new_module)
  File "<frozen importlib._bootstrap_external>", line 839, in exec_module
  File "<frozen importlib._bootstrap_external>", line 976, in get_code
  File "<frozen importlib._bootstrap_external>", line 906, in source_to_code
  File "<frozen importlib._bootstrap>", line 219, in _call_with_frames_removed
  File "/opt/airflow/dags/first_dag.py", line 5
    dag_id-="our first dag"
          ^
SyntaxError: invalid syntax
[2023-12-21T19:47:54.948+0000] {processor.py:842} WARNING - No viable dags retrieved from /opt/airflow/dags/first_dag.py
[2023-12-21T19:47:54.971+0000] {processor.py:183} INFO - Processing /opt/airflow/dags/first_dag.py took 0.043 seconds
[2023-12-21T19:48:00.991+0000] {processor.py:161} INFO - Started process (PID=100) to work on /opt/airflow/dags/first_dag.py
[2023-12-21T19:48:00.992+0000] {processor.py:830} INFO - Processing file /opt/airflow/dags/first_dag.py for tasks to queue
[2023-12-21T19:48:00.995+0000] {logging_mixin.py:188} INFO - [2023-12-21T19:48:00.995+0000] {dagbag.py:538} INFO - Filling up the DagBag from /opt/airflow/dags/first_dag.py
[2023-12-21T19:48:01.001+0000] {logging_mixin.py:188} INFO - [2023-12-21T19:48:00.999+0000] {dagbag.py:348} ERROR - Failed to import: /opt/airflow/dags/first_dag.py
Traceback (most recent call last):
  File "/home/airflow/.local/lib/python3.8/site-packages/airflow/models/dagbag.py", line 344, in parse
    loader.exec_module(new_module)
  File "<frozen importlib._bootstrap_external>", line 839, in exec_module
  File "<frozen importlib._bootstrap_external>", line 976, in get_code
  File "<frozen importlib._bootstrap_external>", line 906, in source_to_code
  File "<frozen importlib._bootstrap>", line 219, in _call_with_frames_removed
  File "/opt/airflow/dags/first_dag.py", line 5
    dag_id-="our first dag",
          ^
SyntaxError: invalid syntax
[2023-12-21T19:48:01.002+0000] {processor.py:842} WARNING - No viable dags retrieved from /opt/airflow/dags/first_dag.py
[2023-12-21T19:48:01.033+0000] {processor.py:183} INFO - Processing /opt/airflow/dags/first_dag.py took 0.046 seconds
[2023-12-21T19:48:06.169+0000] {processor.py:161} INFO - Started process (PID=101) to work on /opt/airflow/dags/first_dag.py
[2023-12-21T19:48:06.171+0000] {processor.py:830} INFO - Processing file /opt/airflow/dags/first_dag.py for tasks to queue
[2023-12-21T19:48:06.176+0000] {logging_mixin.py:188} INFO - [2023-12-21T19:48:06.175+0000] {dagbag.py:538} INFO - Filling up the DagBag from /opt/airflow/dags/first_dag.py
[2023-12-21T19:48:06.181+0000] {logging_mixin.py:188} INFO - [2023-12-21T19:48:06.180+0000] {dagbag.py:348} ERROR - Failed to import: /opt/airflow/dags/first_dag.py
Traceback (most recent call last):
  File "/home/airflow/.local/lib/python3.8/site-packages/airflow/models/dagbag.py", line 344, in parse
    loader.exec_module(new_module)
  File "<frozen importlib._bootstrap_external>", line 843, in exec_module
  File "<frozen importlib._bootstrap>", line 219, in _call_with_frames_removed
  File "/opt/airflow/dags/first_dag.py", line 4, in <module>
    with DAG(
TypeError: __init__() missing 1 required positional argument: 'dag_id'
[2023-12-21T19:48:06.182+0000] {processor.py:842} WARNING - No viable dags retrieved from /opt/airflow/dags/first_dag.py
[2023-12-21T19:48:06.208+0000] {processor.py:183} INFO - Processing /opt/airflow/dags/first_dag.py took 0.051 seconds
[2023-12-21T19:48:07.280+0000] {processor.py:161} INFO - Started process (PID=102) to work on /opt/airflow/dags/first_dag.py
[2023-12-21T19:48:07.281+0000] {processor.py:830} INFO - Processing file /opt/airflow/dags/first_dag.py for tasks to queue
[2023-12-21T19:48:07.286+0000] {logging_mixin.py:188} INFO - [2023-12-21T19:48:07.286+0000] {dagbag.py:538} INFO - Filling up the DagBag from /opt/airflow/dags/first_dag.py
[2023-12-21T19:48:07.293+0000] {logging_mixin.py:188} INFO - [2023-12-21T19:48:07.292+0000] {dagbag.py:348} ERROR - Failed to import: /opt/airflow/dags/first_dag.py
Traceback (most recent call last):
  File "/home/airflow/.local/lib/python3.8/site-packages/airflow/models/dagbag.py", line 344, in parse
    loader.exec_module(new_module)
  File "<frozen importlib._bootstrap_external>", line 843, in exec_module
  File "<frozen importlib._bootstrap>", line 219, in _call_with_frames_removed
  File "/opt/airflow/dags/first_dag.py", line 4, in <module>
    with DAG(
TypeError: __init__() missing 1 required positional argument: 'dag_id'
[2023-12-21T19:48:07.293+0000] {processor.py:842} WARNING - No viable dags retrieved from /opt/airflow/dags/first_dag.py
[2023-12-21T19:48:07.320+0000] {processor.py:183} INFO - Processing /opt/airflow/dags/first_dag.py took 0.056 seconds
[2023-12-21T19:48:08.314+0000] {processor.py:161} INFO - Started process (PID=103) to work on /opt/airflow/dags/first_dag.py
[2023-12-21T19:48:08.315+0000] {processor.py:830} INFO - Processing file /opt/airflow/dags/first_dag.py for tasks to queue
[2023-12-21T19:48:08.319+0000] {logging_mixin.py:188} INFO - [2023-12-21T19:48:08.318+0000] {dagbag.py:538} INFO - Filling up the DagBag from /opt/airflow/dags/first_dag.py
[2023-12-21T19:48:08.325+0000] {logging_mixin.py:188} INFO - [2023-12-21T19:48:08.323+0000] {dagbag.py:348} ERROR - Failed to import: /opt/airflow/dags/first_dag.py
Traceback (most recent call last):
  File "/home/airflow/.local/lib/python3.8/site-packages/airflow/models/dagbag.py", line 344, in parse
    loader.exec_module(new_module)
  File "<frozen importlib._bootstrap_external>", line 843, in exec_module
  File "<frozen importlib._bootstrap>", line 219, in _call_with_frames_removed
  File "/opt/airflow/dags/first_dag.py", line 4, in <module>
    with DAG(
TypeError: __init__() missing 1 required positional argument: 'dag_id'
[2023-12-21T19:48:08.325+0000] {processor.py:842} WARNING - No viable dags retrieved from /opt/airflow/dags/first_dag.py
[2023-12-21T19:48:08.361+0000] {processor.py:183} INFO - Processing /opt/airflow/dags/first_dag.py took 0.054 seconds
[2023-12-21T19:48:12.428+0000] {processor.py:161} INFO - Started process (PID=104) to work on /opt/airflow/dags/first_dag.py
[2023-12-21T19:48:12.437+0000] {processor.py:830} INFO - Processing file /opt/airflow/dags/first_dag.py for tasks to queue
[2023-12-21T19:48:12.443+0000] {logging_mixin.py:188} INFO - [2023-12-21T19:48:12.442+0000] {dagbag.py:538} INFO - Filling up the DagBag from /opt/airflow/dags/first_dag.py
[2023-12-21T19:48:12.451+0000] {logging_mixin.py:188} INFO - [2023-12-21T19:48:12.449+0000] {dagbag.py:348} ERROR - Failed to import: /opt/airflow/dags/first_dag.py
Traceback (most recent call last):
  File "/home/airflow/.local/lib/python3.8/site-packages/airflow/models/dagbag.py", line 344, in parse
    loader.exec_module(new_module)
  File "<frozen importlib._bootstrap_external>", line 839, in exec_module
  File "<frozen importlib._bootstrap_external>", line 976, in get_code
  File "<frozen importlib._bootstrap_external>", line 906, in source_to_code
  File "<frozen importlib._bootstrap>", line 219, in _call_with_frames_removed
  File "/opt/airflow/dags/first_dag.py", line 5
    dag_id-="our first dag",
          ^
SyntaxError: invalid syntax
[2023-12-21T19:48:12.452+0000] {processor.py:842} WARNING - No viable dags retrieved from /opt/airflow/dags/first_dag.py
[2023-12-21T19:48:12.494+0000] {processor.py:183} INFO - Processing /opt/airflow/dags/first_dag.py took 0.075 seconds
[2023-12-21T19:48:19.574+0000] {processor.py:161} INFO - Started process (PID=105) to work on /opt/airflow/dags/first_dag.py
[2023-12-21T19:48:19.583+0000] {processor.py:830} INFO - Processing file /opt/airflow/dags/first_dag.py for tasks to queue
[2023-12-21T19:48:19.588+0000] {logging_mixin.py:188} INFO - [2023-12-21T19:48:19.587+0000] {dagbag.py:538} INFO - Filling up the DagBag from /opt/airflow/dags/first_dag.py
[2023-12-21T19:48:19.595+0000] {logging_mixin.py:188} INFO - [2023-12-21T19:48:19.592+0000] {dagbag.py:348} ERROR - Failed to import: /opt/airflow/dags/first_dag.py
Traceback (most recent call last):
  File "/home/airflow/.local/lib/python3.8/site-packages/airflow/models/dagbag.py", line 344, in parse
    loader.exec_module(new_module)
  File "<frozen importlib._bootstrap_external>", line 843, in exec_module
  File "<frozen importlib._bootstrap>", line 219, in _call_with_frames_removed
  File "/opt/airflow/dags/first_dag.py", line 4, in <module>
    with DAG(
  File "/home/airflow/.local/lib/python3.8/site-packages/airflow/models/dag.py", line 497, in __init__
    validate_key(dag_id)
  File "/home/airflow/.local/lib/python3.8/site-packages/airflow/utils/helpers.py", line 57, in validate_key
    raise AirflowException(
airflow.exceptions.AirflowException: The key 'our first dag' has to be made of alphanumeric characters, dashes, dots and underscores exclusively
[2023-12-21T19:48:19.596+0000] {processor.py:842} WARNING - No viable dags retrieved from /opt/airflow/dags/first_dag.py
[2023-12-21T19:48:19.629+0000] {processor.py:183} INFO - Processing /opt/airflow/dags/first_dag.py took 0.064 seconds
[2023-12-21T19:48:21.670+0000] {processor.py:161} INFO - Started process (PID=112) to work on /opt/airflow/dags/first_dag.py
[2023-12-21T19:48:21.671+0000] {processor.py:830} INFO - Processing file /opt/airflow/dags/first_dag.py for tasks to queue
[2023-12-21T19:48:21.676+0000] {logging_mixin.py:188} INFO - [2023-12-21T19:48:21.676+0000] {dagbag.py:538} INFO - Filling up the DagBag from /opt/airflow/dags/first_dag.py
[2023-12-21T19:48:21.685+0000] {logging_mixin.py:188} INFO - [2023-12-21T19:48:21.681+0000] {dagbag.py:348} ERROR - Failed to import: /opt/airflow/dags/first_dag.py
Traceback (most recent call last):
  File "/home/airflow/.local/lib/python3.8/site-packages/airflow/models/dagbag.py", line 344, in parse
    loader.exec_module(new_module)
  File "<frozen importlib._bootstrap_external>", line 843, in exec_module
  File "<frozen importlib._bootstrap>", line 219, in _call_with_frames_removed
  File "/opt/airflow/dags/first_dag.py", line 4, in <module>
    with DAG(
  File "/home/airflow/.local/lib/python3.8/site-packages/airflow/models/dag.py", line 497, in __init__
    validate_key(dag_id)
  File "/home/airflow/.local/lib/python3.8/site-packages/airflow/utils/helpers.py", line 57, in validate_key
    raise AirflowException(
airflow.exceptions.AirflowException: The key 'our first dag' has to be made of alphanumeric characters, dashes, dots and underscores exclusively
[2023-12-21T19:48:21.685+0000] {processor.py:842} WARNING - No viable dags retrieved from /opt/airflow/dags/first_dag.py
[2023-12-21T19:48:21.740+0000] {processor.py:183} INFO - Processing /opt/airflow/dags/first_dag.py took 0.081 seconds
[2023-12-21T19:48:26.722+0000] {processor.py:161} INFO - Started process (PID=113) to work on /opt/airflow/dags/first_dag.py
[2023-12-21T19:48:26.723+0000] {processor.py:830} INFO - Processing file /opt/airflow/dags/first_dag.py for tasks to queue
[2023-12-21T19:48:26.727+0000] {logging_mixin.py:188} INFO - [2023-12-21T19:48:26.726+0000] {dagbag.py:538} INFO - Filling up the DagBag from /opt/airflow/dags/first_dag.py
[2023-12-21T19:48:26.732+0000] {logging_mixin.py:188} INFO - [2023-12-21T19:48:26.730+0000] {dagbag.py:348} ERROR - Failed to import: /opt/airflow/dags/first_dag.py
Traceback (most recent call last):
  File "/home/airflow/.local/lib/python3.8/site-packages/airflow/models/dagbag.py", line 344, in parse
    loader.exec_module(new_module)
  File "<frozen importlib._bootstrap_external>", line 839, in exec_module
  File "<frozen importlib._bootstrap_external>", line 976, in get_code
  File "<frozen importlib._bootstrap_external>", line 906, in source_to_code
  File "<frozen importlib._bootstrap>", line 219, in _call_with_frames_removed
  File "/opt/airflow/dags/first_dag.py", line 6
    description
    ^
SyntaxError: positional argument follows keyword argument
[2023-12-21T19:48:26.732+0000] {processor.py:842} WARNING - No viable dags retrieved from /opt/airflow/dags/first_dag.py
[2023-12-21T19:48:26.757+0000] {processor.py:183} INFO - Processing /opt/airflow/dags/first_dag.py took 0.039 seconds
[2023-12-21T19:48:28.737+0000] {processor.py:161} INFO - Started process (PID=114) to work on /opt/airflow/dags/first_dag.py
[2023-12-21T19:48:28.738+0000] {processor.py:830} INFO - Processing file /opt/airflow/dags/first_dag.py for tasks to queue
[2023-12-21T19:48:28.742+0000] {logging_mixin.py:188} INFO - [2023-12-21T19:48:28.741+0000] {dagbag.py:538} INFO - Filling up the DagBag from /opt/airflow/dags/first_dag.py
[2023-12-21T19:48:28.746+0000] {logging_mixin.py:188} INFO - [2023-12-21T19:48:28.745+0000] {dagbag.py:348} ERROR - Failed to import: /opt/airflow/dags/first_dag.py
Traceback (most recent call last):
  File "/home/airflow/.local/lib/python3.8/site-packages/airflow/models/dagbag.py", line 344, in parse
    loader.exec_module(new_module)
  File "<frozen importlib._bootstrap_external>", line 839, in exec_module
  File "<frozen importlib._bootstrap_external>", line 976, in get_code
  File "<frozen importlib._bootstrap_external>", line 906, in source_to_code
  File "<frozen importlib._bootstrap>", line 219, in _call_with_frames_removed
  File "/opt/airflow/dags/first_dag.py", line 7
    ) as dag:
    ^
SyntaxError: invalid syntax
[2023-12-21T19:48:28.747+0000] {processor.py:842} WARNING - No viable dags retrieved from /opt/airflow/dags/first_dag.py
[2023-12-21T19:48:28.772+0000] {processor.py:183} INFO - Processing /opt/airflow/dags/first_dag.py took 0.040 seconds
[2023-12-21T19:48:30.833+0000] {processor.py:161} INFO - Started process (PID=115) to work on /opt/airflow/dags/first_dag.py
[2023-12-21T19:48:30.834+0000] {processor.py:830} INFO - Processing file /opt/airflow/dags/first_dag.py for tasks to queue
[2023-12-21T19:48:30.838+0000] {logging_mixin.py:188} INFO - [2023-12-21T19:48:30.837+0000] {dagbag.py:538} INFO - Filling up the DagBag from /opt/airflow/dags/first_dag.py
[2023-12-21T19:48:30.843+0000] {logging_mixin.py:188} INFO - [2023-12-21T19:48:30.841+0000] {dagbag.py:348} ERROR - Failed to import: /opt/airflow/dags/first_dag.py
Traceback (most recent call last):
  File "/home/airflow/.local/lib/python3.8/site-packages/airflow/models/dagbag.py", line 344, in parse
    loader.exec_module(new_module)
  File "<frozen importlib._bootstrap_external>", line 843, in exec_module
  File "<frozen importlib._bootstrap>", line 219, in _call_with_frames_removed
  File "/opt/airflow/dags/first_dag.py", line 4, in <module>
    with DAG(
  File "/home/airflow/.local/lib/python3.8/site-packages/airflow/models/dag.py", line 497, in __init__
    validate_key(dag_id)
  File "/home/airflow/.local/lib/python3.8/site-packages/airflow/utils/helpers.py", line 57, in validate_key
    raise AirflowException(
airflow.exceptions.AirflowException: The key 'our first dag' has to be made of alphanumeric characters, dashes, dots and underscores exclusively
[2023-12-21T19:48:30.844+0000] {processor.py:842} WARNING - No viable dags retrieved from /opt/airflow/dags/first_dag.py
[2023-12-21T19:48:30.866+0000] {processor.py:183} INFO - Processing /opt/airflow/dags/first_dag.py took 0.043 seconds
[2023-12-21T19:48:38.975+0000] {processor.py:161} INFO - Started process (PID=116) to work on /opt/airflow/dags/first_dag.py
[2023-12-21T19:48:38.984+0000] {processor.py:830} INFO - Processing file /opt/airflow/dags/first_dag.py for tasks to queue
[2023-12-21T19:48:38.989+0000] {logging_mixin.py:188} INFO - [2023-12-21T19:48:38.988+0000] {dagbag.py:538} INFO - Filling up the DagBag from /opt/airflow/dags/first_dag.py
[2023-12-21T19:48:38.996+0000] {logging_mixin.py:188} INFO - [2023-12-21T19:48:38.993+0000] {dagbag.py:348} ERROR - Failed to import: /opt/airflow/dags/first_dag.py
Traceback (most recent call last):
  File "/home/airflow/.local/lib/python3.8/site-packages/airflow/models/dagbag.py", line 344, in parse
    loader.exec_module(new_module)
  File "<frozen importlib._bootstrap_external>", line 843, in exec_module
  File "<frozen importlib._bootstrap>", line 219, in _call_with_frames_removed
  File "/opt/airflow/dags/first_dag.py", line 4, in <module>
    with DAG(
  File "/home/airflow/.local/lib/python3.8/site-packages/airflow/models/dag.py", line 497, in __init__
    validate_key(dag_id)
  File "/home/airflow/.local/lib/python3.8/site-packages/airflow/utils/helpers.py", line 57, in validate_key
    raise AirflowException(
airflow.exceptions.AirflowException: The key 'our first dag' has to be made of alphanumeric characters, dashes, dots and underscores exclusively
[2023-12-21T19:48:38.996+0000] {processor.py:842} WARNING - No viable dags retrieved from /opt/airflow/dags/first_dag.py
[2023-12-21T19:48:39.020+0000] {processor.py:183} INFO - Processing /opt/airflow/dags/first_dag.py took 0.057 seconds
[2023-12-21T19:48:42.048+0000] {processor.py:161} INFO - Started process (PID=117) to work on /opt/airflow/dags/first_dag.py
[2023-12-21T19:48:42.051+0000] {processor.py:830} INFO - Processing file /opt/airflow/dags/first_dag.py for tasks to queue
[2023-12-21T19:48:42.064+0000] {logging_mixin.py:188} INFO - [2023-12-21T19:48:42.063+0000] {dagbag.py:538} INFO - Filling up the DagBag from /opt/airflow/dags/first_dag.py
[2023-12-21T19:48:42.074+0000] {logging_mixin.py:188} INFO - [2023-12-21T19:48:42.070+0000] {dagbag.py:348} ERROR - Failed to import: /opt/airflow/dags/first_dag.py
Traceback (most recent call last):
  File "/home/airflow/.local/lib/python3.8/site-packages/airflow/models/dagbag.py", line 344, in parse
    loader.exec_module(new_module)
  File "<frozen importlib._bootstrap_external>", line 843, in exec_module
  File "<frozen importlib._bootstrap>", line 219, in _call_with_frames_removed
  File "/opt/airflow/dags/first_dag.py", line 4, in <module>
    with DAG(
  File "/home/airflow/.local/lib/python3.8/site-packages/airflow/models/dag.py", line 497, in __init__
    validate_key(dag_id)
  File "/home/airflow/.local/lib/python3.8/site-packages/airflow/utils/helpers.py", line 57, in validate_key
    raise AirflowException(
airflow.exceptions.AirflowException: The key 'our first dag' has to be made of alphanumeric characters, dashes, dots and underscores exclusively
[2023-12-21T19:48:42.075+0000] {processor.py:842} WARNING - No viable dags retrieved from /opt/airflow/dags/first_dag.py
[2023-12-21T19:48:42.116+0000] {processor.py:183} INFO - Processing /opt/airflow/dags/first_dag.py took 0.076 seconds
[2023-12-21T19:49:02.236+0000] {processor.py:161} INFO - Started process (PID=124) to work on /opt/airflow/dags/first_dag.py
[2023-12-21T19:49:02.244+0000] {processor.py:830} INFO - Processing file /opt/airflow/dags/first_dag.py for tasks to queue
[2023-12-21T19:49:02.246+0000] {logging_mixin.py:188} INFO - [2023-12-21T19:49:02.246+0000] {dagbag.py:538} INFO - Filling up the DagBag from /opt/airflow/dags/first_dag.py
[2023-12-21T19:49:02.253+0000] {logging_mixin.py:188} INFO - [2023-12-21T19:49:02.250+0000] {dagbag.py:348} ERROR - Failed to import: /opt/airflow/dags/first_dag.py
Traceback (most recent call last):
  File "/home/airflow/.local/lib/python3.8/site-packages/airflow/models/dagbag.py", line 344, in parse
    loader.exec_module(new_module)
  File "<frozen importlib._bootstrap_external>", line 843, in exec_module
  File "<frozen importlib._bootstrap>", line 219, in _call_with_frames_removed
  File "/opt/airflow/dags/first_dag.py", line 4, in <module>
    with DAG(
  File "/home/airflow/.local/lib/python3.8/site-packages/airflow/models/dag.py", line 497, in __init__
    validate_key(dag_id)
  File "/home/airflow/.local/lib/python3.8/site-packages/airflow/utils/helpers.py", line 57, in validate_key
    raise AirflowException(
airflow.exceptions.AirflowException: The key 'our first dag' has to be made of alphanumeric characters, dashes, dots and underscores exclusively
[2023-12-21T19:49:02.254+0000] {processor.py:842} WARNING - No viable dags retrieved from /opt/airflow/dags/first_dag.py
[2023-12-21T19:49:02.292+0000] {processor.py:183} INFO - Processing /opt/airflow/dags/first_dag.py took 0.061 seconds
[2023-12-21T19:49:04.319+0000] {processor.py:161} INFO - Started process (PID=125) to work on /opt/airflow/dags/first_dag.py
[2023-12-21T19:49:04.321+0000] {processor.py:830} INFO - Processing file /opt/airflow/dags/first_dag.py for tasks to queue
[2023-12-21T19:49:04.325+0000] {logging_mixin.py:188} INFO - [2023-12-21T19:49:04.325+0000] {dagbag.py:538} INFO - Filling up the DagBag from /opt/airflow/dags/first_dag.py
[2023-12-21T19:49:04.332+0000] {logging_mixin.py:188} INFO - [2023-12-21T19:49:04.329+0000] {dagbag.py:348} ERROR - Failed to import: /opt/airflow/dags/first_dag.py
Traceback (most recent call last):
  File "/home/airflow/.local/lib/python3.8/site-packages/airflow/models/dagbag.py", line 344, in parse
    loader.exec_module(new_module)
  File "<frozen importlib._bootstrap_external>", line 843, in exec_module
  File "<frozen importlib._bootstrap>", line 219, in _call_with_frames_removed
  File "/opt/airflow/dags/first_dag.py", line 4, in <module>
    with DAG(
  File "/home/airflow/.local/lib/python3.8/site-packages/airflow/models/dag.py", line 497, in __init__
    validate_key(dag_id)
  File "/home/airflow/.local/lib/python3.8/site-packages/airflow/utils/helpers.py", line 57, in validate_key
    raise AirflowException(
airflow.exceptions.AirflowException: The key 'our first dag' has to be made of alphanumeric characters, dashes, dots and underscores exclusively
[2023-12-21T19:49:04.332+0000] {processor.py:842} WARNING - No viable dags retrieved from /opt/airflow/dags/first_dag.py
[2023-12-21T19:49:04.354+0000] {processor.py:183} INFO - Processing /opt/airflow/dags/first_dag.py took 0.043 seconds
[2023-12-21T19:49:06.425+0000] {processor.py:161} INFO - Started process (PID=126) to work on /opt/airflow/dags/first_dag.py
[2023-12-21T19:49:06.429+0000] {processor.py:830} INFO - Processing file /opt/airflow/dags/first_dag.py for tasks to queue
[2023-12-21T19:49:06.444+0000] {logging_mixin.py:188} INFO - [2023-12-21T19:49:06.442+0000] {dagbag.py:538} INFO - Filling up the DagBag from /opt/airflow/dags/first_dag.py
[2023-12-21T19:49:06.459+0000] {logging_mixin.py:188} INFO - [2023-12-21T19:49:06.455+0000] {dagbag.py:348} ERROR - Failed to import: /opt/airflow/dags/first_dag.py
Traceback (most recent call last):
  File "/home/airflow/.local/lib/python3.8/site-packages/airflow/models/dagbag.py", line 344, in parse
    loader.exec_module(new_module)
  File "<frozen importlib._bootstrap_external>", line 843, in exec_module
  File "<frozen importlib._bootstrap>", line 219, in _call_with_frames_removed
  File "/opt/airflow/dags/first_dag.py", line 4, in <module>
    with DAG(
  File "/home/airflow/.local/lib/python3.8/site-packages/airflow/models/dag.py", line 497, in __init__
    validate_key(dag_id)
  File "/home/airflow/.local/lib/python3.8/site-packages/airflow/utils/helpers.py", line 57, in validate_key
    raise AirflowException(
airflow.exceptions.AirflowException: The key 'our first dag' has to be made of alphanumeric characters, dashes, dots and underscores exclusively
[2023-12-21T19:49:06.460+0000] {processor.py:842} WARNING - No viable dags retrieved from /opt/airflow/dags/first_dag.py
[2023-12-21T19:49:06.494+0000] {processor.py:183} INFO - Processing /opt/airflow/dags/first_dag.py took 0.092 seconds
[2023-12-21T19:49:10.495+0000] {processor.py:161} INFO - Started process (PID=127) to work on /opt/airflow/dags/first_dag.py
[2023-12-21T19:49:10.504+0000] {processor.py:830} INFO - Processing file /opt/airflow/dags/first_dag.py for tasks to queue
[2023-12-21T19:49:10.508+0000] {logging_mixin.py:188} INFO - [2023-12-21T19:49:10.508+0000] {dagbag.py:538} INFO - Filling up the DagBag from /opt/airflow/dags/first_dag.py
[2023-12-21T19:49:10.516+0000] {logging_mixin.py:188} INFO - [2023-12-21T19:49:10.512+0000] {dagbag.py:348} ERROR - Failed to import: /opt/airflow/dags/first_dag.py
Traceback (most recent call last):
  File "/home/airflow/.local/lib/python3.8/site-packages/airflow/models/dagbag.py", line 344, in parse
    loader.exec_module(new_module)
  File "<frozen importlib._bootstrap_external>", line 843, in exec_module
  File "<frozen importlib._bootstrap>", line 219, in _call_with_frames_removed
  File "/opt/airflow/dags/first_dag.py", line 4, in <module>
    with DAG(
  File "/home/airflow/.local/lib/python3.8/site-packages/airflow/models/dag.py", line 497, in __init__
    validate_key(dag_id)
  File "/home/airflow/.local/lib/python3.8/site-packages/airflow/utils/helpers.py", line 57, in validate_key
    raise AirflowException(
airflow.exceptions.AirflowException: The key 'our first dag' has to be made of alphanumeric characters, dashes, dots and underscores exclusively
[2023-12-21T19:49:10.516+0000] {processor.py:842} WARNING - No viable dags retrieved from /opt/airflow/dags/first_dag.py
[2023-12-21T19:49:10.546+0000] {processor.py:183} INFO - Processing /opt/airflow/dags/first_dag.py took 0.057 seconds
[2023-12-21T19:49:12.635+0000] {processor.py:161} INFO - Started process (PID=128) to work on /opt/airflow/dags/first_dag.py
[2023-12-21T19:49:12.641+0000] {processor.py:830} INFO - Processing file /opt/airflow/dags/first_dag.py for tasks to queue
[2023-12-21T19:49:12.660+0000] {logging_mixin.py:188} INFO - [2023-12-21T19:49:12.658+0000] {dagbag.py:538} INFO - Filling up the DagBag from /opt/airflow/dags/first_dag.py
[2023-12-21T19:49:12.675+0000] {logging_mixin.py:188} INFO - [2023-12-21T19:49:12.669+0000] {dagbag.py:348} ERROR - Failed to import: /opt/airflow/dags/first_dag.py
Traceback (most recent call last):
  File "/home/airflow/.local/lib/python3.8/site-packages/airflow/models/dagbag.py", line 344, in parse
    loader.exec_module(new_module)
  File "<frozen importlib._bootstrap_external>", line 843, in exec_module
  File "<frozen importlib._bootstrap>", line 219, in _call_with_frames_removed
  File "/opt/airflow/dags/first_dag.py", line 4, in <module>
    with DAG(
  File "/home/airflow/.local/lib/python3.8/site-packages/airflow/models/dag.py", line 497, in __init__
    validate_key(dag_id)
  File "/home/airflow/.local/lib/python3.8/site-packages/airflow/utils/helpers.py", line 57, in validate_key
    raise AirflowException(
airflow.exceptions.AirflowException: The key 'our first dag' has to be made of alphanumeric characters, dashes, dots and underscores exclusively
[2023-12-21T19:49:12.676+0000] {processor.py:842} WARNING - No viable dags retrieved from /opt/airflow/dags/first_dag.py
[2023-12-21T19:49:12.706+0000] {processor.py:183} INFO - Processing /opt/airflow/dags/first_dag.py took 0.101 seconds
[2023-12-21T19:49:13.690+0000] {processor.py:161} INFO - Started process (PID=129) to work on /opt/airflow/dags/first_dag.py
[2023-12-21T19:49:13.691+0000] {processor.py:830} INFO - Processing file /opt/airflow/dags/first_dag.py for tasks to queue
[2023-12-21T19:49:13.694+0000] {logging_mixin.py:188} INFO - [2023-12-21T19:49:13.694+0000] {dagbag.py:538} INFO - Filling up the DagBag from /opt/airflow/dags/first_dag.py
[2023-12-21T19:49:13.701+0000] {logging_mixin.py:188} INFO - [2023-12-21T19:49:13.698+0000] {dagbag.py:348} ERROR - Failed to import: /opt/airflow/dags/first_dag.py
Traceback (most recent call last):
  File "/home/airflow/.local/lib/python3.8/site-packages/airflow/models/dagbag.py", line 344, in parse
    loader.exec_module(new_module)
  File "<frozen importlib._bootstrap_external>", line 843, in exec_module
  File "<frozen importlib._bootstrap>", line 219, in _call_with_frames_removed
  File "/opt/airflow/dags/first_dag.py", line 4, in <module>
    with DAG(
  File "/home/airflow/.local/lib/python3.8/site-packages/airflow/models/dag.py", line 497, in __init__
    validate_key(dag_id)
  File "/home/airflow/.local/lib/python3.8/site-packages/airflow/utils/helpers.py", line 57, in validate_key
    raise AirflowException(
airflow.exceptions.AirflowException: The key 'our first dag' has to be made of alphanumeric characters, dashes, dots and underscores exclusively
[2023-12-21T19:49:13.701+0000] {processor.py:842} WARNING - No viable dags retrieved from /opt/airflow/dags/first_dag.py
[2023-12-21T19:49:13.725+0000] {processor.py:183} INFO - Processing /opt/airflow/dags/first_dag.py took 0.042 seconds
[2023-12-21T19:49:15.805+0000] {processor.py:161} INFO - Started process (PID=130) to work on /opt/airflow/dags/first_dag.py
[2023-12-21T19:49:15.814+0000] {processor.py:830} INFO - Processing file /opt/airflow/dags/first_dag.py for tasks to queue
[2023-12-21T19:49:15.818+0000] {logging_mixin.py:188} INFO - [2023-12-21T19:49:15.818+0000] {dagbag.py:538} INFO - Filling up the DagBag from /opt/airflow/dags/first_dag.py
[2023-12-21T19:49:15.826+0000] {logging_mixin.py:188} INFO - [2023-12-21T19:49:15.823+0000] {dagbag.py:348} ERROR - Failed to import: /opt/airflow/dags/first_dag.py
Traceback (most recent call last):
  File "/home/airflow/.local/lib/python3.8/site-packages/airflow/models/dagbag.py", line 344, in parse
    loader.exec_module(new_module)
  File "<frozen importlib._bootstrap_external>", line 843, in exec_module
  File "<frozen importlib._bootstrap>", line 219, in _call_with_frames_removed
  File "/opt/airflow/dags/first_dag.py", line 4, in <module>
    with DAG(
  File "/home/airflow/.local/lib/python3.8/site-packages/airflow/models/dag.py", line 497, in __init__
    validate_key(dag_id)
  File "/home/airflow/.local/lib/python3.8/site-packages/airflow/utils/helpers.py", line 57, in validate_key
    raise AirflowException(
airflow.exceptions.AirflowException: The key 'our first dag' has to be made of alphanumeric characters, dashes, dots and underscores exclusively
[2023-12-21T19:49:15.826+0000] {processor.py:842} WARNING - No viable dags retrieved from /opt/airflow/dags/first_dag.py
[2023-12-21T19:49:15.853+0000] {processor.py:183} INFO - Processing /opt/airflow/dags/first_dag.py took 0.065 seconds
[2023-12-21T19:49:29.973+0000] {processor.py:161} INFO - Started process (PID=137) to work on /opt/airflow/dags/first_dag.py
[2023-12-21T19:49:29.985+0000] {processor.py:830} INFO - Processing file /opt/airflow/dags/first_dag.py for tasks to queue
[2023-12-21T19:49:29.988+0000] {logging_mixin.py:188} INFO - [2023-12-21T19:49:29.988+0000] {dagbag.py:538} INFO - Filling up the DagBag from /opt/airflow/dags/first_dag.py
[2023-12-21T19:49:30.000+0000] {logging_mixin.py:188} INFO - [2023-12-21T19:49:29.994+0000] {dagbag.py:348} ERROR - Failed to import: /opt/airflow/dags/first_dag.py
Traceback (most recent call last):
  File "/home/airflow/.local/lib/python3.8/site-packages/airflow/models/dagbag.py", line 344, in parse
    loader.exec_module(new_module)
  File "<frozen importlib._bootstrap_external>", line 843, in exec_module
  File "<frozen importlib._bootstrap>", line 219, in _call_with_frames_removed
  File "/opt/airflow/dags/first_dag.py", line 5, in <module>
    with DAG(
  File "/home/airflow/.local/lib/python3.8/site-packages/airflow/models/dag.py", line 497, in __init__
    validate_key(dag_id)
  File "/home/airflow/.local/lib/python3.8/site-packages/airflow/utils/helpers.py", line 57, in validate_key
    raise AirflowException(
airflow.exceptions.AirflowException: The key 'our first dag' has to be made of alphanumeric characters, dashes, dots and underscores exclusively
[2023-12-21T19:49:30.000+0000] {processor.py:842} WARNING - No viable dags retrieved from /opt/airflow/dags/first_dag.py
[2023-12-21T19:49:30.038+0000] {processor.py:183} INFO - Processing /opt/airflow/dags/first_dag.py took 0.072 seconds
[2023-12-21T19:49:39.082+0000] {processor.py:161} INFO - Started process (PID=138) to work on /opt/airflow/dags/first_dag.py
[2023-12-21T19:49:39.093+0000] {processor.py:830} INFO - Processing file /opt/airflow/dags/first_dag.py for tasks to queue
[2023-12-21T19:49:39.107+0000] {logging_mixin.py:188} INFO - [2023-12-21T19:49:39.102+0000] {dagbag.py:538} INFO - Filling up the DagBag from /opt/airflow/dags/first_dag.py
[2023-12-21T19:49:39.121+0000] {logging_mixin.py:188} INFO - [2023-12-21T19:49:39.116+0000] {dagbag.py:348} ERROR - Failed to import: /opt/airflow/dags/first_dag.py
Traceback (most recent call last):
  File "/home/airflow/.local/lib/python3.8/site-packages/airflow/models/dagbag.py", line 344, in parse
    loader.exec_module(new_module)
  File "<frozen importlib._bootstrap_external>", line 843, in exec_module
  File "<frozen importlib._bootstrap>", line 219, in _call_with_frames_removed
  File "/opt/airflow/dags/first_dag.py", line 5, in <module>
    with DAG(
  File "/home/airflow/.local/lib/python3.8/site-packages/airflow/models/dag.py", line 497, in __init__
    validate_key(dag_id)
  File "/home/airflow/.local/lib/python3.8/site-packages/airflow/utils/helpers.py", line 57, in validate_key
    raise AirflowException(
airflow.exceptions.AirflowException: The key 'our first dag' has to be made of alphanumeric characters, dashes, dots and underscores exclusively
[2023-12-21T19:49:39.122+0000] {processor.py:842} WARNING - No viable dags retrieved from /opt/airflow/dags/first_dag.py
[2023-12-21T19:49:39.159+0000] {processor.py:183} INFO - Processing /opt/airflow/dags/first_dag.py took 0.090 seconds
[2023-12-21T19:49:40.183+0000] {processor.py:161} INFO - Started process (PID=139) to work on /opt/airflow/dags/first_dag.py
[2023-12-21T19:49:40.186+0000] {processor.py:830} INFO - Processing file /opt/airflow/dags/first_dag.py for tasks to queue
[2023-12-21T19:49:40.196+0000] {logging_mixin.py:188} INFO - [2023-12-21T19:49:40.195+0000] {dagbag.py:538} INFO - Filling up the DagBag from /opt/airflow/dags/first_dag.py
[2023-12-21T19:49:40.208+0000] {logging_mixin.py:188} INFO - [2023-12-21T19:49:40.203+0000] {dagbag.py:348} ERROR - Failed to import: /opt/airflow/dags/first_dag.py
Traceback (most recent call last):
  File "/home/airflow/.local/lib/python3.8/site-packages/airflow/models/dagbag.py", line 344, in parse
    loader.exec_module(new_module)
  File "<frozen importlib._bootstrap_external>", line 843, in exec_module
  File "<frozen importlib._bootstrap>", line 219, in _call_with_frames_removed
  File "/opt/airflow/dags/first_dag.py", line 5, in <module>
    with DAG(
  File "/home/airflow/.local/lib/python3.8/site-packages/airflow/models/dag.py", line 497, in __init__
    validate_key(dag_id)
  File "/home/airflow/.local/lib/python3.8/site-packages/airflow/utils/helpers.py", line 57, in validate_key
    raise AirflowException(
airflow.exceptions.AirflowException: The key 'our first dag' has to be made of alphanumeric characters, dashes, dots and underscores exclusively
[2023-12-21T19:49:40.209+0000] {processor.py:842} WARNING - No viable dags retrieved from /opt/airflow/dags/first_dag.py
[2023-12-21T19:49:40.242+0000] {processor.py:183} INFO - Processing /opt/airflow/dags/first_dag.py took 0.081 seconds
[2023-12-21T19:49:42.277+0000] {processor.py:161} INFO - Started process (PID=140) to work on /opt/airflow/dags/first_dag.py
[2023-12-21T19:49:42.279+0000] {processor.py:830} INFO - Processing file /opt/airflow/dags/first_dag.py for tasks to queue
[2023-12-21T19:49:42.283+0000] {logging_mixin.py:188} INFO - [2023-12-21T19:49:42.282+0000] {dagbag.py:538} INFO - Filling up the DagBag from /opt/airflow/dags/first_dag.py
[2023-12-21T19:49:42.291+0000] {logging_mixin.py:188} INFO - [2023-12-21T19:49:42.287+0000] {dagbag.py:348} ERROR - Failed to import: /opt/airflow/dags/first_dag.py
Traceback (most recent call last):
  File "/home/airflow/.local/lib/python3.8/site-packages/airflow/models/dagbag.py", line 344, in parse
    loader.exec_module(new_module)
  File "<frozen importlib._bootstrap_external>", line 843, in exec_module
  File "<frozen importlib._bootstrap>", line 219, in _call_with_frames_removed
  File "/opt/airflow/dags/first_dag.py", line 5, in <module>
    with DAG(
  File "/home/airflow/.local/lib/python3.8/site-packages/airflow/models/dag.py", line 497, in __init__
    validate_key(dag_id)
  File "/home/airflow/.local/lib/python3.8/site-packages/airflow/utils/helpers.py", line 57, in validate_key
    raise AirflowException(
airflow.exceptions.AirflowException: The key 'our first dag' has to be made of alphanumeric characters, dashes, dots and underscores exclusively
[2023-12-21T19:49:42.292+0000] {processor.py:842} WARNING - No viable dags retrieved from /opt/airflow/dags/first_dag.py
[2023-12-21T19:49:42.322+0000] {processor.py:183} INFO - Processing /opt/airflow/dags/first_dag.py took 0.055 seconds
[2023-12-21T19:49:48.363+0000] {processor.py:161} INFO - Started process (PID=141) to work on /opt/airflow/dags/first_dag.py
[2023-12-21T19:49:48.372+0000] {processor.py:830} INFO - Processing file /opt/airflow/dags/first_dag.py for tasks to queue
[2023-12-21T19:49:48.374+0000] {logging_mixin.py:188} INFO - [2023-12-21T19:49:48.374+0000] {dagbag.py:538} INFO - Filling up the DagBag from /opt/airflow/dags/first_dag.py
[2023-12-21T19:49:48.381+0000] {logging_mixin.py:188} INFO - [2023-12-21T19:49:48.378+0000] {dagbag.py:348} ERROR - Failed to import: /opt/airflow/dags/first_dag.py
Traceback (most recent call last):
  File "/home/airflow/.local/lib/python3.8/site-packages/airflow/models/dagbag.py", line 344, in parse
    loader.exec_module(new_module)
  File "<frozen importlib._bootstrap_external>", line 843, in exec_module
  File "<frozen importlib._bootstrap>", line 219, in _call_with_frames_removed
  File "/opt/airflow/dags/first_dag.py", line 5, in <module>
    with DAG(
  File "/home/airflow/.local/lib/python3.8/site-packages/airflow/models/dag.py", line 497, in __init__
    validate_key(dag_id)
  File "/home/airflow/.local/lib/python3.8/site-packages/airflow/utils/helpers.py", line 57, in validate_key
    raise AirflowException(
airflow.exceptions.AirflowException: The key 'our first dag' has to be made of alphanumeric characters, dashes, dots and underscores exclusively
[2023-12-21T19:49:48.381+0000] {processor.py:842} WARNING - No viable dags retrieved from /opt/airflow/dags/first_dag.py
[2023-12-21T19:49:48.408+0000] {processor.py:183} INFO - Processing /opt/airflow/dags/first_dag.py took 0.050 seconds
[2023-12-21T19:49:53.475+0000] {processor.py:161} INFO - Started process (PID=148) to work on /opt/airflow/dags/first_dag.py
[2023-12-21T19:49:53.483+0000] {processor.py:830} INFO - Processing file /opt/airflow/dags/first_dag.py for tasks to queue
[2023-12-21T19:49:53.487+0000] {logging_mixin.py:188} INFO - [2023-12-21T19:49:53.487+0000] {dagbag.py:538} INFO - Filling up the DagBag from /opt/airflow/dags/first_dag.py
[2023-12-21T19:49:53.493+0000] {logging_mixin.py:188} INFO - [2023-12-21T19:49:53.492+0000] {dagbag.py:348} ERROR - Failed to import: /opt/airflow/dags/first_dag.py
Traceback (most recent call last):
  File "/home/airflow/.local/lib/python3.8/site-packages/airflow/models/dagbag.py", line 344, in parse
    loader.exec_module(new_module)
  File "<frozen importlib._bootstrap_external>", line 843, in exec_module
  File "<frozen importlib._bootstrap>", line 219, in _call_with_frames_removed
  File "/opt/airflow/dags/first_dag.py", line 8, in <module>
    start_date=datetime()
TypeError: function missing required argument 'year' (pos 1)
[2023-12-21T19:49:53.494+0000] {processor.py:842} WARNING - No viable dags retrieved from /opt/airflow/dags/first_dag.py
[2023-12-21T19:49:53.539+0000] {processor.py:183} INFO - Processing /opt/airflow/dags/first_dag.py took 0.071 seconds
[2023-12-21T19:49:55.599+0000] {processor.py:161} INFO - Started process (PID=149) to work on /opt/airflow/dags/first_dag.py
[2023-12-21T19:49:55.602+0000] {processor.py:830} INFO - Processing file /opt/airflow/dags/first_dag.py for tasks to queue
[2023-12-21T19:49:55.609+0000] {logging_mixin.py:188} INFO - [2023-12-21T19:49:55.608+0000] {dagbag.py:538} INFO - Filling up the DagBag from /opt/airflow/dags/first_dag.py
[2023-12-21T19:49:55.617+0000] {logging_mixin.py:188} INFO - [2023-12-21T19:49:55.615+0000] {dagbag.py:348} ERROR - Failed to import: /opt/airflow/dags/first_dag.py
Traceback (most recent call last):
  File "/home/airflow/.local/lib/python3.8/site-packages/airflow/models/dagbag.py", line 344, in parse
    loader.exec_module(new_module)
  File "<frozen importlib._bootstrap_external>", line 843, in exec_module
  File "<frozen importlib._bootstrap>", line 219, in _call_with_frames_removed
  File "/opt/airflow/dags/first_dag.py", line 8, in <module>
    start_date=datetime(),
TypeError: function missing required argument 'year' (pos 1)
[2023-12-21T19:49:55.618+0000] {processor.py:842} WARNING - No viable dags retrieved from /opt/airflow/dags/first_dag.py
[2023-12-21T19:49:55.654+0000] {processor.py:183} INFO - Processing /opt/airflow/dags/first_dag.py took 0.081 seconds
[2023-12-21T19:49:56.707+0000] {processor.py:161} INFO - Started process (PID=150) to work on /opt/airflow/dags/first_dag.py
[2023-12-21T19:49:56.708+0000] {processor.py:830} INFO - Processing file /opt/airflow/dags/first_dag.py for tasks to queue
[2023-12-21T19:49:56.713+0000] {logging_mixin.py:188} INFO - [2023-12-21T19:49:56.712+0000] {dagbag.py:538} INFO - Filling up the DagBag from /opt/airflow/dags/first_dag.py
[2023-12-21T19:49:56.718+0000] {logging_mixin.py:188} INFO - [2023-12-21T19:49:56.717+0000] {dagbag.py:348} ERROR - Failed to import: /opt/airflow/dags/first_dag.py
Traceback (most recent call last):
  File "/home/airflow/.local/lib/python3.8/site-packages/airflow/models/dagbag.py", line 344, in parse
    loader.exec_module(new_module)
  File "<frozen importlib._bootstrap_external>", line 843, in exec_module
  File "<frozen importlib._bootstrap>", line 219, in _call_with_frames_removed
  File "/opt/airflow/dags/first_dag.py", line 8, in <module>
    start_date=datetime(),  #
TypeError: function missing required argument 'year' (pos 1)
[2023-12-21T19:49:56.719+0000] {processor.py:842} WARNING - No viable dags retrieved from /opt/airflow/dags/first_dag.py
[2023-12-21T19:49:56.753+0000] {processor.py:183} INFO - Processing /opt/airflow/dags/first_dag.py took 0.054 seconds
[2023-12-21T19:49:57.795+0000] {processor.py:161} INFO - Started process (PID=151) to work on /opt/airflow/dags/first_dag.py
[2023-12-21T19:49:57.799+0000] {processor.py:830} INFO - Processing file /opt/airflow/dags/first_dag.py for tasks to queue
[2023-12-21T19:49:57.810+0000] {logging_mixin.py:188} INFO - [2023-12-21T19:49:57.809+0000] {dagbag.py:538} INFO - Filling up the DagBag from /opt/airflow/dags/first_dag.py
[2023-12-21T19:49:57.825+0000] {logging_mixin.py:188} INFO - [2023-12-21T19:49:57.822+0000] {dagbag.py:348} ERROR - Failed to import: /opt/airflow/dags/first_dag.py
Traceback (most recent call last):
  File "/home/airflow/.local/lib/python3.8/site-packages/airflow/models/dagbag.py", line 344, in parse
    loader.exec_module(new_module)
  File "<frozen importlib._bootstrap_external>", line 843, in exec_module
  File "<frozen importlib._bootstrap>", line 219, in _call_with_frames_removed
  File "/opt/airflow/dags/first_dag.py", line 8, in <module>
    start_date=datetime(),  #
TypeError: function missing required argument 'year' (pos 1)
[2023-12-21T19:49:57.826+0000] {processor.py:842} WARNING - No viable dags retrieved from /opt/airflow/dags/first_dag.py
[2023-12-21T19:49:57.866+0000] {processor.py:183} INFO - Processing /opt/airflow/dags/first_dag.py took 0.096 seconds
[2023-12-21T19:50:10.910+0000] {processor.py:161} INFO - Started process (PID=152) to work on /opt/airflow/dags/first_dag.py
[2023-12-21T19:50:10.911+0000] {processor.py:830} INFO - Processing file /opt/airflow/dags/first_dag.py for tasks to queue
[2023-12-21T19:50:10.915+0000] {logging_mixin.py:188} INFO - [2023-12-21T19:50:10.914+0000] {dagbag.py:538} INFO - Filling up the DagBag from /opt/airflow/dags/first_dag.py
[2023-12-21T19:50:10.920+0000] {logging_mixin.py:188} INFO - [2023-12-21T19:50:10.919+0000] {dagbag.py:348} ERROR - Failed to import: /opt/airflow/dags/first_dag.py
Traceback (most recent call last):
  File "/home/airflow/.local/lib/python3.8/site-packages/airflow/models/dagbag.py", line 344, in parse
    loader.exec_module(new_module)
  File "<frozen importlib._bootstrap_external>", line 843, in exec_module
  File "<frozen importlib._bootstrap>", line 219, in _call_with_frames_removed
  File "/opt/airflow/dags/first_dag.py", line 8, in <module>
    start_date=datetime(),  # Starting
TypeError: function missing required argument 'year' (pos 1)
[2023-12-21T19:50:10.921+0000] {processor.py:842} WARNING - No viable dags retrieved from /opt/airflow/dags/first_dag.py
[2023-12-21T19:50:10.960+0000] {processor.py:183} INFO - Processing /opt/airflow/dags/first_dag.py took 0.056 seconds
[2023-12-21T19:50:14.988+0000] {processor.py:161} INFO - Started process (PID=153) to work on /opt/airflow/dags/first_dag.py
[2023-12-21T19:50:14.989+0000] {processor.py:830} INFO - Processing file /opt/airflow/dags/first_dag.py for tasks to queue
[2023-12-21T19:50:14.992+0000] {logging_mixin.py:188} INFO - [2023-12-21T19:50:14.991+0000] {dagbag.py:538} INFO - Filling up the DagBag from /opt/airflow/dags/first_dag.py
[2023-12-21T19:50:14.997+0000] {logging_mixin.py:188} INFO - [2023-12-21T19:50:14.996+0000] {dagbag.py:348} ERROR - Failed to import: /opt/airflow/dags/first_dag.py
Traceback (most recent call last):
  File "/home/airflow/.local/lib/python3.8/site-packages/airflow/models/dagbag.py", line 344, in parse
    loader.exec_module(new_module)
  File "<frozen importlib._bootstrap_external>", line 843, in exec_module
  File "<frozen importlib._bootstrap>", line 219, in _call_with_frames_removed
  File "/opt/airflow/dags/first_dag.py", line 8, in <module>
    start_date=datetime(),  # Starting date of the date
TypeError: function missing required argument 'year' (pos 1)
[2023-12-21T19:50:14.997+0000] {processor.py:842} WARNING - No viable dags retrieved from /opt/airflow/dags/first_dag.py
[2023-12-21T19:50:15.020+0000] {processor.py:183} INFO - Processing /opt/airflow/dags/first_dag.py took 0.036 seconds
[2023-12-21T19:50:18.047+0000] {processor.py:161} INFO - Started process (PID=154) to work on /opt/airflow/dags/first_dag.py
[2023-12-21T19:50:18.056+0000] {processor.py:830} INFO - Processing file /opt/airflow/dags/first_dag.py for tasks to queue
[2023-12-21T19:50:18.061+0000] {logging_mixin.py:188} INFO - [2023-12-21T19:50:18.060+0000] {dagbag.py:538} INFO - Filling up the DagBag from /opt/airflow/dags/first_dag.py
[2023-12-21T19:50:18.066+0000] {logging_mixin.py:188} INFO - [2023-12-21T19:50:18.065+0000] {dagbag.py:348} ERROR - Failed to import: /opt/airflow/dags/first_dag.py
Traceback (most recent call last):
  File "/home/airflow/.local/lib/python3.8/site-packages/airflow/models/dagbag.py", line 344, in parse
    loader.exec_module(new_module)
  File "<frozen importlib._bootstrap_external>", line 843, in exec_module
  File "<frozen importlib._bootstrap>", line 219, in _call_with_frames_removed
  File "/opt/airflow/dags/first_dag.py", line 8, in <module>
    start_date=datetime(),  # Starting date of the date
TypeError: function missing required argument 'year' (pos 1)
[2023-12-21T19:50:18.067+0000] {processor.py:842} WARNING - No viable dags retrieved from /opt/airflow/dags/first_dag.py
[2023-12-21T19:50:18.108+0000] {processor.py:183} INFO - Processing /opt/airflow/dags/first_dag.py took 0.069 seconds
[2023-12-21T19:50:25.127+0000] {processor.py:161} INFO - Started process (PID=161) to work on /opt/airflow/dags/first_dag.py
[2023-12-21T19:50:25.135+0000] {processor.py:830} INFO - Processing file /opt/airflow/dags/first_dag.py for tasks to queue
[2023-12-21T19:50:25.137+0000] {logging_mixin.py:188} INFO - [2023-12-21T19:50:25.137+0000] {dagbag.py:538} INFO - Filling up the DagBag from /opt/airflow/dags/first_dag.py
[2023-12-21T19:50:25.141+0000] {logging_mixin.py:188} INFO - [2023-12-21T19:50:25.140+0000] {dagbag.py:348} ERROR - Failed to import: /opt/airflow/dags/first_dag.py
Traceback (most recent call last):
  File "/home/airflow/.local/lib/python3.8/site-packages/airflow/models/dagbag.py", line 344, in parse
    loader.exec_module(new_module)
  File "<frozen importlib._bootstrap_external>", line 843, in exec_module
  File "<frozen importlib._bootstrap>", line 219, in _call_with_frames_removed
  File "/opt/airflow/dags/first_dag.py", line 8, in <module>
    start_date=datetime(),  # Starting date of the date
TypeError: function missing required argument 'year' (pos 1)
[2023-12-21T19:50:25.142+0000] {processor.py:842} WARNING - No viable dags retrieved from /opt/airflow/dags/first_dag.py
[2023-12-21T19:50:25.165+0000] {processor.py:183} INFO - Processing /opt/airflow/dags/first_dag.py took 0.044 seconds
[2023-12-21T19:50:46.274+0000] {processor.py:161} INFO - Started process (PID=162) to work on /opt/airflow/dags/first_dag.py
[2023-12-21T19:50:46.276+0000] {processor.py:830} INFO - Processing file /opt/airflow/dags/first_dag.py for tasks to queue
[2023-12-21T19:50:46.279+0000] {logging_mixin.py:188} INFO - [2023-12-21T19:50:46.279+0000] {dagbag.py:538} INFO - Filling up the DagBag from /opt/airflow/dags/first_dag.py
[2023-12-21T19:50:46.283+0000] {logging_mixin.py:188} INFO - [2023-12-21T19:50:46.282+0000] {dagbag.py:348} ERROR - Failed to import: /opt/airflow/dags/first_dag.py
Traceback (most recent call last):
  File "/home/airflow/.local/lib/python3.8/site-packages/airflow/models/dagbag.py", line 344, in parse
    loader.exec_module(new_module)
  File "<frozen importlib._bootstrap_external>", line 843, in exec_module
  File "<frozen importlib._bootstrap>", line 219, in _call_with_frames_removed
  File "/opt/airflow/dags/first_dag.py", line 8, in <module>
    start_date=datetime(2023),  # Starting date of the date
TypeError: function missing required argument 'month' (pos 2)
[2023-12-21T19:50:46.284+0000] {processor.py:842} WARNING - No viable dags retrieved from /opt/airflow/dags/first_dag.py
[2023-12-21T19:50:46.308+0000] {processor.py:183} INFO - Processing /opt/airflow/dags/first_dag.py took 0.039 seconds
[2023-12-21T19:50:49.354+0000] {processor.py:161} INFO - Started process (PID=163) to work on /opt/airflow/dags/first_dag.py
[2023-12-21T19:50:49.355+0000] {processor.py:830} INFO - Processing file /opt/airflow/dags/first_dag.py for tasks to queue
[2023-12-21T19:50:49.359+0000] {logging_mixin.py:188} INFO - [2023-12-21T19:50:49.358+0000] {dagbag.py:538} INFO - Filling up the DagBag from /opt/airflow/dags/first_dag.py
[2023-12-21T19:50:49.365+0000] {logging_mixin.py:188} INFO - [2023-12-21T19:50:49.362+0000] {dagbag.py:348} ERROR - Failed to import: /opt/airflow/dags/first_dag.py
Traceback (most recent call last):
  File "/home/airflow/.local/lib/python3.8/site-packages/airflow/models/dagbag.py", line 344, in parse
    loader.exec_module(new_module)
  File "<frozen importlib._bootstrap_external>", line 843, in exec_module
  File "<frozen importlib._bootstrap>", line 219, in _call_with_frames_removed
  File "/opt/airflow/dags/first_dag.py", line 5, in <module>
    with DAG(
  File "/home/airflow/.local/lib/python3.8/site-packages/airflow/models/dag.py", line 497, in __init__
    validate_key(dag_id)
  File "/home/airflow/.local/lib/python3.8/site-packages/airflow/utils/helpers.py", line 57, in validate_key
    raise AirflowException(
airflow.exceptions.AirflowException: The key 'our first dag' has to be made of alphanumeric characters, dashes, dots and underscores exclusively
[2023-12-21T19:50:49.365+0000] {processor.py:842} WARNING - No viable dags retrieved from /opt/airflow/dags/first_dag.py
[2023-12-21T19:50:49.388+0000] {processor.py:183} INFO - Processing /opt/airflow/dags/first_dag.py took 0.042 seconds
[2023-12-21T19:50:53.392+0000] {processor.py:161} INFO - Started process (PID=170) to work on /opt/airflow/dags/first_dag.py
[2023-12-21T19:50:53.394+0000] {processor.py:830} INFO - Processing file /opt/airflow/dags/first_dag.py for tasks to queue
[2023-12-21T19:50:53.397+0000] {logging_mixin.py:188} INFO - [2023-12-21T19:50:53.397+0000] {dagbag.py:538} INFO - Filling up the DagBag from /opt/airflow/dags/first_dag.py
[2023-12-21T19:50:53.404+0000] {logging_mixin.py:188} INFO - [2023-12-21T19:50:53.401+0000] {dagbag.py:348} ERROR - Failed to import: /opt/airflow/dags/first_dag.py
Traceback (most recent call last):
  File "/home/airflow/.local/lib/python3.8/site-packages/airflow/models/dagbag.py", line 344, in parse
    loader.exec_module(new_module)
  File "<frozen importlib._bootstrap_external>", line 843, in exec_module
  File "<frozen importlib._bootstrap>", line 219, in _call_with_frames_removed
  File "/opt/airflow/dags/first_dag.py", line 5, in <module>
    with DAG(
  File "/home/airflow/.local/lib/python3.8/site-packages/airflow/models/dag.py", line 497, in __init__
    validate_key(dag_id)
  File "/home/airflow/.local/lib/python3.8/site-packages/airflow/utils/helpers.py", line 57, in validate_key
    raise AirflowException(
airflow.exceptions.AirflowException: The key 'our first dag' has to be made of alphanumeric characters, dashes, dots and underscores exclusively
[2023-12-21T19:50:53.405+0000] {processor.py:842} WARNING - No viable dags retrieved from /opt/airflow/dags/first_dag.py
[2023-12-21T19:50:53.436+0000] {processor.py:183} INFO - Processing /opt/airflow/dags/first_dag.py took 0.048 seconds
[2023-12-21T19:51:07.543+0000] {processor.py:161} INFO - Started process (PID=171) to work on /opt/airflow/dags/first_dag.py
[2023-12-21T19:51:07.551+0000] {processor.py:830} INFO - Processing file /opt/airflow/dags/first_dag.py for tasks to queue
[2023-12-21T19:51:07.555+0000] {logging_mixin.py:188} INFO - [2023-12-21T19:51:07.555+0000] {dagbag.py:538} INFO - Filling up the DagBag from /opt/airflow/dags/first_dag.py
[2023-12-21T19:51:07.563+0000] {logging_mixin.py:188} INFO - [2023-12-21T19:51:07.560+0000] {dagbag.py:348} ERROR - Failed to import: /opt/airflow/dags/first_dag.py
Traceback (most recent call last):
  File "/home/airflow/.local/lib/python3.8/site-packages/airflow/models/dagbag.py", line 344, in parse
    loader.exec_module(new_module)
  File "<frozen importlib._bootstrap_external>", line 843, in exec_module
  File "<frozen importlib._bootstrap>", line 219, in _call_with_frames_removed
  File "/opt/airflow/dags/first_dag.py", line 5, in <module>
    with DAG(
  File "/home/airflow/.local/lib/python3.8/site-packages/airflow/models/dag.py", line 497, in __init__
    validate_key(dag_id)
  File "/home/airflow/.local/lib/python3.8/site-packages/airflow/utils/helpers.py", line 57, in validate_key
    raise AirflowException(
airflow.exceptions.AirflowException: The key 'our first dag' has to be made of alphanumeric characters, dashes, dots and underscores exclusively
[2023-12-21T19:51:07.563+0000] {processor.py:842} WARNING - No viable dags retrieved from /opt/airflow/dags/first_dag.py
[2023-12-21T19:51:07.601+0000] {processor.py:183} INFO - Processing /opt/airflow/dags/first_dag.py took 0.065 seconds
[2023-12-21T19:51:09.596+0000] {processor.py:161} INFO - Started process (PID=172) to work on /opt/airflow/dags/first_dag.py
[2023-12-21T19:51:09.598+0000] {processor.py:830} INFO - Processing file /opt/airflow/dags/first_dag.py for tasks to queue
[2023-12-21T19:51:09.602+0000] {logging_mixin.py:188} INFO - [2023-12-21T19:51:09.602+0000] {dagbag.py:538} INFO - Filling up the DagBag from /opt/airflow/dags/first_dag.py
[2023-12-21T19:51:09.611+0000] {logging_mixin.py:188} INFO - [2023-12-21T19:51:09.607+0000] {dagbag.py:348} ERROR - Failed to import: /opt/airflow/dags/first_dag.py
Traceback (most recent call last):
  File "/home/airflow/.local/lib/python3.8/site-packages/airflow/models/dagbag.py", line 344, in parse
    loader.exec_module(new_module)
  File "<frozen importlib._bootstrap_external>", line 843, in exec_module
  File "<frozen importlib._bootstrap>", line 219, in _call_with_frames_removed
  File "/opt/airflow/dags/first_dag.py", line 5, in <module>
    with DAG(
  File "/home/airflow/.local/lib/python3.8/site-packages/airflow/models/dag.py", line 497, in __init__
    validate_key(dag_id)
  File "/home/airflow/.local/lib/python3.8/site-packages/airflow/utils/helpers.py", line 57, in validate_key
    raise AirflowException(
airflow.exceptions.AirflowException: The key 'our first dag' has to be made of alphanumeric characters, dashes, dots and underscores exclusively
[2023-12-21T19:51:09.611+0000] {processor.py:842} WARNING - No viable dags retrieved from /opt/airflow/dags/first_dag.py
[2023-12-21T19:51:09.635+0000] {processor.py:183} INFO - Processing /opt/airflow/dags/first_dag.py took 0.046 seconds
[2023-12-21T19:51:27.792+0000] {processor.py:161} INFO - Started process (PID=179) to work on /opt/airflow/dags/first_dag.py
[2023-12-21T19:51:27.793+0000] {processor.py:830} INFO - Processing file /opt/airflow/dags/first_dag.py for tasks to queue
[2023-12-21T19:51:27.797+0000] {logging_mixin.py:188} INFO - [2023-12-21T19:51:27.796+0000] {dagbag.py:538} INFO - Filling up the DagBag from /opt/airflow/dags/first_dag.py
[2023-12-21T19:51:27.803+0000] {logging_mixin.py:188} INFO - [2023-12-21T19:51:27.801+0000] {dagbag.py:348} ERROR - Failed to import: /opt/airflow/dags/first_dag.py
Traceback (most recent call last):
  File "/home/airflow/.local/lib/python3.8/site-packages/airflow/models/dagbag.py", line 344, in parse
    loader.exec_module(new_module)
  File "<frozen importlib._bootstrap_external>", line 843, in exec_module
  File "<frozen importlib._bootstrap>", line 219, in _call_with_frames_removed
  File "/opt/airflow/dags/first_dag.py", line 5, in <module>
    with DAG(
  File "/home/airflow/.local/lib/python3.8/site-packages/airflow/models/dag.py", line 497, in __init__
    validate_key(dag_id)
  File "/home/airflow/.local/lib/python3.8/site-packages/airflow/utils/helpers.py", line 57, in validate_key
    raise AirflowException(
airflow.exceptions.AirflowException: The key 'our first dag' has to be made of alphanumeric characters, dashes, dots and underscores exclusively
[2023-12-21T19:51:27.803+0000] {processor.py:842} WARNING - No viable dags retrieved from /opt/airflow/dags/first_dag.py
[2023-12-21T19:51:27.825+0000] {processor.py:183} INFO - Processing /opt/airflow/dags/first_dag.py took 0.040 seconds
[2023-12-21T19:51:30.864+0000] {processor.py:161} INFO - Started process (PID=180) to work on /opt/airflow/dags/first_dag.py
[2023-12-21T19:51:30.866+0000] {processor.py:830} INFO - Processing file /opt/airflow/dags/first_dag.py for tasks to queue
[2023-12-21T19:51:30.869+0000] {logging_mixin.py:188} INFO - [2023-12-21T19:51:30.869+0000] {dagbag.py:538} INFO - Filling up the DagBag from /opt/airflow/dags/first_dag.py
[2023-12-21T19:51:30.875+0000] {logging_mixin.py:188} INFO - [2023-12-21T19:51:30.873+0000] {dagbag.py:348} ERROR - Failed to import: /opt/airflow/dags/first_dag.py
Traceback (most recent call last):
  File "/home/airflow/.local/lib/python3.8/site-packages/airflow/models/dagbag.py", line 344, in parse
    loader.exec_module(new_module)
  File "<frozen importlib._bootstrap_external>", line 843, in exec_module
  File "<frozen importlib._bootstrap>", line 219, in _call_with_frames_removed
  File "/opt/airflow/dags/first_dag.py", line 5, in <module>
    with DAG(
  File "/home/airflow/.local/lib/python3.8/site-packages/airflow/models/dag.py", line 497, in __init__
    validate_key(dag_id)
  File "/home/airflow/.local/lib/python3.8/site-packages/airflow/utils/helpers.py", line 57, in validate_key
    raise AirflowException(
airflow.exceptions.AirflowException: The key 'our first dag' has to be made of alphanumeric characters, dashes, dots and underscores exclusively
[2023-12-21T19:51:30.875+0000] {processor.py:842} WARNING - No viable dags retrieved from /opt/airflow/dags/first_dag.py
[2023-12-21T19:51:30.897+0000] {processor.py:183} INFO - Processing /opt/airflow/dags/first_dag.py took 0.039 seconds
[2023-12-21T19:51:33.928+0000] {processor.py:161} INFO - Started process (PID=181) to work on /opt/airflow/dags/first_dag.py
[2023-12-21T19:51:33.929+0000] {processor.py:830} INFO - Processing file /opt/airflow/dags/first_dag.py for tasks to queue
[2023-12-21T19:51:33.932+0000] {logging_mixin.py:188} INFO - [2023-12-21T19:51:33.932+0000] {dagbag.py:538} INFO - Filling up the DagBag from /opt/airflow/dags/first_dag.py
[2023-12-21T19:51:33.937+0000] {logging_mixin.py:188} INFO - [2023-12-21T19:51:33.935+0000] {dagbag.py:348} ERROR - Failed to import: /opt/airflow/dags/first_dag.py
Traceback (most recent call last):
  File "/home/airflow/.local/lib/python3.8/site-packages/airflow/models/dagbag.py", line 344, in parse
    loader.exec_module(new_module)
  File "<frozen importlib._bootstrap_external>", line 843, in exec_module
  File "<frozen importlib._bootstrap>", line 219, in _call_with_frames_removed
  File "/opt/airflow/dags/first_dag.py", line 5, in <module>
    with DAG(
  File "/home/airflow/.local/lib/python3.8/site-packages/airflow/models/dag.py", line 497, in __init__
    validate_key(dag_id)
  File "/home/airflow/.local/lib/python3.8/site-packages/airflow/utils/helpers.py", line 57, in validate_key
    raise AirflowException(
airflow.exceptions.AirflowException: The key 'our first dag' has to be made of alphanumeric characters, dashes, dots and underscores exclusively
[2023-12-21T19:51:33.938+0000] {processor.py:842} WARNING - No viable dags retrieved from /opt/airflow/dags/first_dag.py
[2023-12-21T19:51:33.963+0000] {processor.py:183} INFO - Processing /opt/airflow/dags/first_dag.py took 0.042 seconds
[2023-12-21T19:51:38.070+0000] {processor.py:161} INFO - Started process (PID=182) to work on /opt/airflow/dags/first_dag.py
[2023-12-21T19:51:38.073+0000] {processor.py:830} INFO - Processing file /opt/airflow/dags/first_dag.py for tasks to queue
[2023-12-21T19:51:38.081+0000] {logging_mixin.py:188} INFO - [2023-12-21T19:51:38.080+0000] {dagbag.py:538} INFO - Filling up the DagBag from /opt/airflow/dags/first_dag.py
[2023-12-21T19:51:38.093+0000] {logging_mixin.py:188} INFO - [2023-12-21T19:51:38.088+0000] {dagbag.py:348} ERROR - Failed to import: /opt/airflow/dags/first_dag.py
Traceback (most recent call last):
  File "/home/airflow/.local/lib/python3.8/site-packages/airflow/models/dagbag.py", line 344, in parse
    loader.exec_module(new_module)
  File "<frozen importlib._bootstrap_external>", line 843, in exec_module
  File "<frozen importlib._bootstrap>", line 219, in _call_with_frames_removed
  File "/opt/airflow/dags/first_dag.py", line 5, in <module>
    with DAG(
  File "/home/airflow/.local/lib/python3.8/site-packages/airflow/models/dag.py", line 497, in __init__
    validate_key(dag_id)
  File "/home/airflow/.local/lib/python3.8/site-packages/airflow/utils/helpers.py", line 57, in validate_key
    raise AirflowException(
airflow.exceptions.AirflowException: The key 'our first dag' has to be made of alphanumeric characters, dashes, dots and underscores exclusively
[2023-12-21T19:51:38.094+0000] {processor.py:842} WARNING - No viable dags retrieved from /opt/airflow/dags/first_dag.py
[2023-12-21T19:51:38.129+0000] {processor.py:183} INFO - Processing /opt/airflow/dags/first_dag.py took 0.089 seconds
[2023-12-21T19:51:39.097+0000] {processor.py:161} INFO - Started process (PID=183) to work on /opt/airflow/dags/first_dag.py
[2023-12-21T19:51:39.098+0000] {processor.py:830} INFO - Processing file /opt/airflow/dags/first_dag.py for tasks to queue
[2023-12-21T19:51:39.101+0000] {logging_mixin.py:188} INFO - [2023-12-21T19:51:39.101+0000] {dagbag.py:538} INFO - Filling up the DagBag from /opt/airflow/dags/first_dag.py
[2023-12-21T19:51:39.109+0000] {logging_mixin.py:188} INFO - [2023-12-21T19:51:39.106+0000] {dagbag.py:348} ERROR - Failed to import: /opt/airflow/dags/first_dag.py
Traceback (most recent call last):
  File "/home/airflow/.local/lib/python3.8/site-packages/airflow/models/dagbag.py", line 344, in parse
    loader.exec_module(new_module)
  File "<frozen importlib._bootstrap_external>", line 843, in exec_module
  File "<frozen importlib._bootstrap>", line 219, in _call_with_frames_removed
  File "/opt/airflow/dags/first_dag.py", line 5, in <module>
    with DAG(
  File "/home/airflow/.local/lib/python3.8/site-packages/airflow/models/dag.py", line 497, in __init__
    validate_key(dag_id)
  File "/home/airflow/.local/lib/python3.8/site-packages/airflow/utils/helpers.py", line 57, in validate_key
    raise AirflowException(
airflow.exceptions.AirflowException: The key 'our first dag' has to be made of alphanumeric characters, dashes, dots and underscores exclusively
[2023-12-21T19:51:39.109+0000] {processor.py:842} WARNING - No viable dags retrieved from /opt/airflow/dags/first_dag.py
[2023-12-21T19:51:39.134+0000] {processor.py:183} INFO - Processing /opt/airflow/dags/first_dag.py took 0.040 seconds
[2023-12-21T19:51:41.160+0000] {processor.py:161} INFO - Started process (PID=184) to work on /opt/airflow/dags/first_dag.py
[2023-12-21T19:51:41.162+0000] {processor.py:830} INFO - Processing file /opt/airflow/dags/first_dag.py for tasks to queue
[2023-12-21T19:51:41.168+0000] {logging_mixin.py:188} INFO - [2023-12-21T19:51:41.168+0000] {dagbag.py:538} INFO - Filling up the DagBag from /opt/airflow/dags/first_dag.py
[2023-12-21T19:51:41.177+0000] {logging_mixin.py:188} INFO - [2023-12-21T19:51:41.174+0000] {dagbag.py:348} ERROR - Failed to import: /opt/airflow/dags/first_dag.py
Traceback (most recent call last):
  File "/home/airflow/.local/lib/python3.8/site-packages/airflow/models/dagbag.py", line 344, in parse
    loader.exec_module(new_module)
  File "<frozen importlib._bootstrap_external>", line 843, in exec_module
  File "<frozen importlib._bootstrap>", line 219, in _call_with_frames_removed
  File "/opt/airflow/dags/first_dag.py", line 5, in <module>
    with DAG(
  File "/home/airflow/.local/lib/python3.8/site-packages/airflow/models/dag.py", line 497, in __init__
    validate_key(dag_id)
  File "/home/airflow/.local/lib/python3.8/site-packages/airflow/utils/helpers.py", line 57, in validate_key
    raise AirflowException(
airflow.exceptions.AirflowException: The key 'our first dag' has to be made of alphanumeric characters, dashes, dots and underscores exclusively
[2023-12-21T19:51:41.178+0000] {processor.py:842} WARNING - No viable dags retrieved from /opt/airflow/dags/first_dag.py
[2023-12-21T19:51:41.216+0000] {processor.py:183} INFO - Processing /opt/airflow/dags/first_dag.py took 0.066 seconds
[2023-12-21T19:51:42.214+0000] {processor.py:161} INFO - Started process (PID=185) to work on /opt/airflow/dags/first_dag.py
[2023-12-21T19:51:42.215+0000] {processor.py:830} INFO - Processing file /opt/airflow/dags/first_dag.py for tasks to queue
[2023-12-21T19:51:42.220+0000] {logging_mixin.py:188} INFO - [2023-12-21T19:51:42.220+0000] {dagbag.py:538} INFO - Filling up the DagBag from /opt/airflow/dags/first_dag.py
[2023-12-21T19:51:42.229+0000] {logging_mixin.py:188} INFO - [2023-12-21T19:51:42.226+0000] {dagbag.py:348} ERROR - Failed to import: /opt/airflow/dags/first_dag.py
Traceback (most recent call last):
  File "/home/airflow/.local/lib/python3.8/site-packages/airflow/models/dagbag.py", line 344, in parse
    loader.exec_module(new_module)
  File "<frozen importlib._bootstrap_external>", line 843, in exec_module
  File "<frozen importlib._bootstrap>", line 219, in _call_with_frames_removed
  File "/opt/airflow/dags/first_dag.py", line 5, in <module>
    with DAG(
  File "/home/airflow/.local/lib/python3.8/site-packages/airflow/models/dag.py", line 497, in __init__
    validate_key(dag_id)
  File "/home/airflow/.local/lib/python3.8/site-packages/airflow/utils/helpers.py", line 57, in validate_key
    raise AirflowException(
airflow.exceptions.AirflowException: The key 'our first dag' has to be made of alphanumeric characters, dashes, dots and underscores exclusively
[2023-12-21T19:51:42.230+0000] {processor.py:842} WARNING - No viable dags retrieved from /opt/airflow/dags/first_dag.py
[2023-12-21T19:51:42.275+0000] {processor.py:183} INFO - Processing /opt/airflow/dags/first_dag.py took 0.069 seconds
[2023-12-21T19:52:12.493+0000] {processor.py:161} INFO - Started process (PID=192) to work on /opt/airflow/dags/first_dag.py
[2023-12-21T19:52:12.494+0000] {processor.py:830} INFO - Processing file /opt/airflow/dags/first_dag.py for tasks to queue
[2023-12-21T19:52:12.501+0000] {logging_mixin.py:188} INFO - [2023-12-21T19:52:12.501+0000] {dagbag.py:538} INFO - Filling up the DagBag from /opt/airflow/dags/first_dag.py
[2023-12-21T19:52:12.510+0000] {logging_mixin.py:188} INFO - [2023-12-21T19:52:12.505+0000] {dagbag.py:348} ERROR - Failed to import: /opt/airflow/dags/first_dag.py
Traceback (most recent call last):
  File "/home/airflow/.local/lib/python3.8/site-packages/airflow/models/dagbag.py", line 344, in parse
    loader.exec_module(new_module)
  File "<frozen importlib._bootstrap_external>", line 843, in exec_module
  File "<frozen importlib._bootstrap>", line 219, in _call_with_frames_removed
  File "/opt/airflow/dags/first_dag.py", line 5, in <module>
    with DAG(
  File "/home/airflow/.local/lib/python3.8/site-packages/airflow/models/dag.py", line 497, in __init__
    validate_key(dag_id)
  File "/home/airflow/.local/lib/python3.8/site-packages/airflow/utils/helpers.py", line 57, in validate_key
    raise AirflowException(
airflow.exceptions.AirflowException: The key 'our first dag' has to be made of alphanumeric characters, dashes, dots and underscores exclusively
[2023-12-21T19:52:12.511+0000] {processor.py:842} WARNING - No viable dags retrieved from /opt/airflow/dags/first_dag.py
[2023-12-21T19:52:12.537+0000] {processor.py:183} INFO - Processing /opt/airflow/dags/first_dag.py took 0.053 seconds
[2023-12-21T19:52:35.704+0000] {processor.py:161} INFO - Started process (PID=199) to work on /opt/airflow/dags/first_dag.py
[2023-12-21T19:52:35.712+0000] {processor.py:830} INFO - Processing file /opt/airflow/dags/first_dag.py for tasks to queue
[2023-12-21T19:52:35.715+0000] {logging_mixin.py:188} INFO - [2023-12-21T19:52:35.715+0000] {dagbag.py:538} INFO - Filling up the DagBag from /opt/airflow/dags/first_dag.py
[2023-12-21T19:52:35.719+0000] {logging_mixin.py:188} INFO - [2023-12-21T19:52:35.718+0000] {dagbag.py:348} ERROR - Failed to import: /opt/airflow/dags/first_dag.py
Traceback (most recent call last):
  File "/home/airflow/.local/lib/python3.8/site-packages/airflow/models/dagbag.py", line 344, in parse
    loader.exec_module(new_module)
  File "<frozen importlib._bootstrap_external>", line 839, in exec_module
  File "<frozen importlib._bootstrap_external>", line 976, in get_code
  File "<frozen importlib._bootstrap_external>", line 906, in source_to_code
  File "<frozen importlib._bootstrap>", line 219, in _call_with_frames_removed
  File "/opt/airflow/dags/first_dag.py", line 10
    ) as dag:
    ^
SyntaxError: invalid syntax
[2023-12-21T19:52:35.720+0000] {processor.py:842} WARNING - No viable dags retrieved from /opt/airflow/dags/first_dag.py
[2023-12-21T19:52:35.744+0000] {processor.py:183} INFO - Processing /opt/airflow/dags/first_dag.py took 0.045 seconds
[2023-12-21T19:52:40.824+0000] {processor.py:161} INFO - Started process (PID=200) to work on /opt/airflow/dags/first_dag.py
[2023-12-21T19:52:40.827+0000] {processor.py:830} INFO - Processing file /opt/airflow/dags/first_dag.py for tasks to queue
[2023-12-21T19:52:40.833+0000] {logging_mixin.py:188} INFO - [2023-12-21T19:52:40.832+0000] {dagbag.py:538} INFO - Filling up the DagBag from /opt/airflow/dags/first_dag.py
[2023-12-21T19:52:40.840+0000] {logging_mixin.py:188} INFO - [2023-12-21T19:52:40.838+0000] {dagbag.py:348} ERROR - Failed to import: /opt/airflow/dags/first_dag.py
Traceback (most recent call last):
  File "/home/airflow/.local/lib/python3.8/site-packages/airflow/models/dagbag.py", line 344, in parse
    loader.exec_module(new_module)
  File "<frozen importlib._bootstrap_external>", line 843, in exec_module
  File "<frozen importlib._bootstrap>", line 219, in _call_with_frames_removed
  File "/opt/airflow/dags/first_dag.py", line 5, in <module>
    with DAG(
TypeError: __init__() got an unexpected keyword argument 'scheduler_interval'
[2023-12-21T19:52:40.841+0000] {processor.py:842} WARNING - No viable dags retrieved from /opt/airflow/dags/first_dag.py
[2023-12-21T19:52:40.867+0000] {processor.py:183} INFO - Processing /opt/airflow/dags/first_dag.py took 0.064 seconds
[2023-12-21T19:52:49.008+0000] {processor.py:161} INFO - Started process (PID=201) to work on /opt/airflow/dags/first_dag.py
[2023-12-21T19:52:49.010+0000] {processor.py:830} INFO - Processing file /opt/airflow/dags/first_dag.py for tasks to queue
[2023-12-21T19:52:49.016+0000] {logging_mixin.py:188} INFO - [2023-12-21T19:52:49.015+0000] {dagbag.py:538} INFO - Filling up the DagBag from /opt/airflow/dags/first_dag.py
[2023-12-21T19:52:49.027+0000] {logging_mixin.py:188} INFO - [2023-12-21T19:52:49.023+0000] {dagbag.py:348} ERROR - Failed to import: /opt/airflow/dags/first_dag.py
Traceback (most recent call last):
  File "/home/airflow/.local/lib/python3.8/site-packages/airflow/models/dagbag.py", line 344, in parse
    loader.exec_module(new_module)
  File "<frozen importlib._bootstrap_external>", line 843, in exec_module
  File "<frozen importlib._bootstrap>", line 219, in _call_with_frames_removed
  File "/opt/airflow/dags/first_dag.py", line 7, in <module>
    with DAG(
TypeError: __init__() got an unexpected keyword argument 'scheduler_interval'
[2023-12-21T19:52:49.028+0000] {processor.py:842} WARNING - No viable dags retrieved from /opt/airflow/dags/first_dag.py
[2023-12-21T19:52:49.080+0000] {processor.py:183} INFO - Processing /opt/airflow/dags/first_dag.py took 0.085 seconds
[2023-12-21T19:52:53.063+0000] {processor.py:161} INFO - Started process (PID=208) to work on /opt/airflow/dags/first_dag.py
[2023-12-21T19:52:53.064+0000] {processor.py:830} INFO - Processing file /opt/airflow/dags/first_dag.py for tasks to queue
[2023-12-21T19:52:53.067+0000] {logging_mixin.py:188} INFO - [2023-12-21T19:52:53.067+0000] {dagbag.py:538} INFO - Filling up the DagBag from /opt/airflow/dags/first_dag.py
[2023-12-21T19:52:53.073+0000] {logging_mixin.py:188} INFO - [2023-12-21T19:52:53.072+0000] {dagbag.py:348} ERROR - Failed to import: /opt/airflow/dags/first_dag.py
Traceback (most recent call last):
  File "/home/airflow/.local/lib/python3.8/site-packages/airflow/models/dagbag.py", line 344, in parse
    loader.exec_module(new_module)
  File "<frozen importlib._bootstrap_external>", line 843, in exec_module
  File "<frozen importlib._bootstrap>", line 219, in _call_with_frames_removed
  File "/opt/airflow/dags/first_dag.py", line 5, in <module>
    default_args
NameError: name 'default_args' is not defined
[2023-12-21T19:52:53.074+0000] {processor.py:842} WARNING - No viable dags retrieved from /opt/airflow/dags/first_dag.py
[2023-12-21T19:52:53.110+0000] {processor.py:183} INFO - Processing /opt/airflow/dags/first_dag.py took 0.054 seconds
[2023-12-21T19:52:56.167+0000] {processor.py:161} INFO - Started process (PID=209) to work on /opt/airflow/dags/first_dag.py
[2023-12-21T19:52:56.169+0000] {processor.py:830} INFO - Processing file /opt/airflow/dags/first_dag.py for tasks to queue
[2023-12-21T19:52:56.172+0000] {logging_mixin.py:188} INFO - [2023-12-21T19:52:56.171+0000] {dagbag.py:538} INFO - Filling up the DagBag from /opt/airflow/dags/first_dag.py
[2023-12-21T19:52:56.179+0000] {logging_mixin.py:188} INFO - [2023-12-21T19:52:56.178+0000] {dagbag.py:348} ERROR - Failed to import: /opt/airflow/dags/first_dag.py
Traceback (most recent call last):
  File "/home/airflow/.local/lib/python3.8/site-packages/airflow/models/dagbag.py", line 344, in parse
    loader.exec_module(new_module)
  File "<frozen importlib._bootstrap_external>", line 843, in exec_module
  File "<frozen importlib._bootstrap>", line 219, in _call_with_frames_removed
  File "/opt/airflow/dags/first_dag.py", line 10, in <module>
    with DAG(
TypeError: __init__() got an unexpected keyword argument 'scheduler_interval'
[2023-12-21T19:52:56.180+0000] {processor.py:842} WARNING - No viable dags retrieved from /opt/airflow/dags/first_dag.py
[2023-12-21T19:52:56.207+0000] {processor.py:183} INFO - Processing /opt/airflow/dags/first_dag.py took 0.046 seconds
[2023-12-21T19:53:01.211+0000] {processor.py:161} INFO - Started process (PID=210) to work on /opt/airflow/dags/first_dag.py
[2023-12-21T19:53:01.213+0000] {processor.py:830} INFO - Processing file /opt/airflow/dags/first_dag.py for tasks to queue
[2023-12-21T19:53:01.218+0000] {logging_mixin.py:188} INFO - [2023-12-21T19:53:01.217+0000] {dagbag.py:538} INFO - Filling up the DagBag from /opt/airflow/dags/first_dag.py
[2023-12-21T19:53:01.224+0000] {logging_mixin.py:188} INFO - [2023-12-21T19:53:01.223+0000] {dagbag.py:348} ERROR - Failed to import: /opt/airflow/dags/first_dag.py
Traceback (most recent call last):
  File "/home/airflow/.local/lib/python3.8/site-packages/airflow/models/dagbag.py", line 344, in parse
    loader.exec_module(new_module)
  File "<frozen importlib._bootstrap_external>", line 843, in exec_module
  File "<frozen importlib._bootstrap>", line 219, in _call_with_frames_removed
  File "/opt/airflow/dags/first_dag.py", line 10, in <module>
    with DAG(
TypeError: __init__() got an unexpected keyword argument 'scheduler_interval'
[2023-12-21T19:53:01.225+0000] {processor.py:842} WARNING - No viable dags retrieved from /opt/airflow/dags/first_dag.py
[2023-12-21T19:53:01.259+0000] {processor.py:183} INFO - Processing /opt/airflow/dags/first_dag.py took 0.054 seconds
[2023-12-21T19:53:05.298+0000] {processor.py:161} INFO - Started process (PID=211) to work on /opt/airflow/dags/first_dag.py
[2023-12-21T19:53:05.300+0000] {processor.py:830} INFO - Processing file /opt/airflow/dags/first_dag.py for tasks to queue
[2023-12-21T19:53:05.304+0000] {logging_mixin.py:188} INFO - [2023-12-21T19:53:05.304+0000] {dagbag.py:538} INFO - Filling up the DagBag from /opt/airflow/dags/first_dag.py
[2023-12-21T19:53:05.309+0000] {logging_mixin.py:188} INFO - [2023-12-21T19:53:05.308+0000] {dagbag.py:348} ERROR - Failed to import: /opt/airflow/dags/first_dag.py
Traceback (most recent call last):
  File "/home/airflow/.local/lib/python3.8/site-packages/airflow/models/dagbag.py", line 344, in parse
    loader.exec_module(new_module)
  File "<frozen importlib._bootstrap_external>", line 843, in exec_module
  File "<frozen importlib._bootstrap>", line 219, in _call_with_frames_removed
  File "/opt/airflow/dags/first_dag.py", line 10, in <module>
    with DAG(
TypeError: __init__() got an unexpected keyword argument 'scheduler_interval'
[2023-12-21T19:53:05.309+0000] {processor.py:842} WARNING - No viable dags retrieved from /opt/airflow/dags/first_dag.py
[2023-12-21T19:53:05.338+0000] {processor.py:183} INFO - Processing /opt/airflow/dags/first_dag.py took 0.045 seconds
[2023-12-21T19:53:07.348+0000] {processor.py:161} INFO - Started process (PID=212) to work on /opt/airflow/dags/first_dag.py
[2023-12-21T19:53:07.350+0000] {processor.py:830} INFO - Processing file /opt/airflow/dags/first_dag.py for tasks to queue
[2023-12-21T19:53:07.356+0000] {logging_mixin.py:188} INFO - [2023-12-21T19:53:07.355+0000] {dagbag.py:538} INFO - Filling up the DagBag from /opt/airflow/dags/first_dag.py
[2023-12-21T19:53:07.363+0000] {logging_mixin.py:188} INFO - [2023-12-21T19:53:07.361+0000] {dagbag.py:348} ERROR - Failed to import: /opt/airflow/dags/first_dag.py
Traceback (most recent call last):
  File "/home/airflow/.local/lib/python3.8/site-packages/airflow/models/dagbag.py", line 344, in parse
    loader.exec_module(new_module)
  File "<frozen importlib._bootstrap_external>", line 839, in exec_module
  File "<frozen importlib._bootstrap_external>", line 976, in get_code
  File "<frozen importlib._bootstrap_external>", line 906, in source_to_code
  File "<frozen importlib._bootstrap>", line 219, in _call_with_frames_removed
  File "/opt/airflow/dags/first_dag.py", line 7
    }
    ^
SyntaxError: invalid syntax
[2023-12-21T19:53:07.364+0000] {processor.py:842} WARNING - No viable dags retrieved from /opt/airflow/dags/first_dag.py
[2023-12-21T19:53:07.408+0000] {processor.py:183} INFO - Processing /opt/airflow/dags/first_dag.py took 0.069 seconds
[2023-12-21T19:53:09.427+0000] {processor.py:161} INFO - Started process (PID=213) to work on /opt/airflow/dags/first_dag.py
[2023-12-21T19:53:09.436+0000] {processor.py:830} INFO - Processing file /opt/airflow/dags/first_dag.py for tasks to queue
[2023-12-21T19:53:09.439+0000] {logging_mixin.py:188} INFO - [2023-12-21T19:53:09.439+0000] {dagbag.py:538} INFO - Filling up the DagBag from /opt/airflow/dags/first_dag.py
[2023-12-21T19:53:09.444+0000] {logging_mixin.py:188} INFO - [2023-12-21T19:53:09.443+0000] {dagbag.py:348} ERROR - Failed to import: /opt/airflow/dags/first_dag.py
Traceback (most recent call last):
  File "/home/airflow/.local/lib/python3.8/site-packages/airflow/models/dagbag.py", line 344, in parse
    loader.exec_module(new_module)
  File "<frozen importlib._bootstrap_external>", line 843, in exec_module
  File "<frozen importlib._bootstrap>", line 219, in _call_with_frames_removed
  File "/opt/airflow/dags/first_dag.py", line 10, in <module>
    with DAG(
TypeError: __init__() got an unexpected keyword argument 'scheduler_interval'
[2023-12-21T19:53:09.444+0000] {processor.py:842} WARNING - No viable dags retrieved from /opt/airflow/dags/first_dag.py
[2023-12-21T19:53:09.471+0000] {processor.py:183} INFO - Processing /opt/airflow/dags/first_dag.py took 0.049 seconds
[2023-12-21T19:53:11.467+0000] {processor.py:161} INFO - Started process (PID=214) to work on /opt/airflow/dags/first_dag.py
[2023-12-21T19:53:11.468+0000] {processor.py:830} INFO - Processing file /opt/airflow/dags/first_dag.py for tasks to queue
[2023-12-21T19:53:11.472+0000] {logging_mixin.py:188} INFO - [2023-12-21T19:53:11.472+0000] {dagbag.py:538} INFO - Filling up the DagBag from /opt/airflow/dags/first_dag.py
[2023-12-21T19:53:11.480+0000] {logging_mixin.py:188} INFO - [2023-12-21T19:53:11.478+0000] {dagbag.py:348} ERROR - Failed to import: /opt/airflow/dags/first_dag.py
Traceback (most recent call last):
  File "/home/airflow/.local/lib/python3.8/site-packages/airflow/models/dagbag.py", line 344, in parse
    loader.exec_module(new_module)
  File "<frozen importlib._bootstrap_external>", line 843, in exec_module
  File "<frozen importlib._bootstrap>", line 219, in _call_with_frames_removed
  File "/opt/airflow/dags/first_dag.py", line 10, in <module>
    with DAG(
TypeError: __init__() got an unexpected keyword argument 'scheduler_interval'
[2023-12-21T19:53:11.481+0000] {processor.py:842} WARNING - No viable dags retrieved from /opt/airflow/dags/first_dag.py
[2023-12-21T19:53:11.514+0000] {processor.py:183} INFO - Processing /opt/airflow/dags/first_dag.py took 0.053 seconds
[2023-12-21T19:53:19.579+0000] {processor.py:161} INFO - Started process (PID=215) to work on /opt/airflow/dags/first_dag.py
[2023-12-21T19:53:19.581+0000] {processor.py:830} INFO - Processing file /opt/airflow/dags/first_dag.py for tasks to queue
[2023-12-21T19:53:19.584+0000] {logging_mixin.py:188} INFO - [2023-12-21T19:53:19.584+0000] {dagbag.py:538} INFO - Filling up the DagBag from /opt/airflow/dags/first_dag.py
[2023-12-21T19:53:19.591+0000] {logging_mixin.py:188} INFO - [2023-12-21T19:53:19.589+0000] {dagbag.py:348} ERROR - Failed to import: /opt/airflow/dags/first_dag.py
Traceback (most recent call last):
  File "/home/airflow/.local/lib/python3.8/site-packages/airflow/models/dagbag.py", line 344, in parse
    loader.exec_module(new_module)
  File "<frozen importlib._bootstrap_external>", line 843, in exec_module
  File "<frozen importlib._bootstrap>", line 219, in _call_with_frames_removed
  File "/opt/airflow/dags/first_dag.py", line 10, in <module>
    with DAG(
TypeError: __init__() got an unexpected keyword argument 'scheduler_interval'
[2023-12-21T19:53:19.591+0000] {processor.py:842} WARNING - No viable dags retrieved from /opt/airflow/dags/first_dag.py
[2023-12-21T19:53:19.620+0000] {processor.py:183} INFO - Processing /opt/airflow/dags/first_dag.py took 0.048 seconds
[2023-12-21T19:53:21.686+0000] {processor.py:161} INFO - Started process (PID=216) to work on /opt/airflow/dags/first_dag.py
[2023-12-21T19:53:21.690+0000] {processor.py:830} INFO - Processing file /opt/airflow/dags/first_dag.py for tasks to queue
[2023-12-21T19:53:21.697+0000] {logging_mixin.py:188} INFO - [2023-12-21T19:53:21.696+0000] {dagbag.py:538} INFO - Filling up the DagBag from /opt/airflow/dags/first_dag.py
[2023-12-21T19:53:21.707+0000] {logging_mixin.py:188} INFO - [2023-12-21T19:53:21.704+0000] {dagbag.py:348} ERROR - Failed to import: /opt/airflow/dags/first_dag.py
Traceback (most recent call last):
  File "/home/airflow/.local/lib/python3.8/site-packages/airflow/models/dagbag.py", line 344, in parse
    loader.exec_module(new_module)
  File "<frozen importlib._bootstrap_external>", line 843, in exec_module
  File "<frozen importlib._bootstrap>", line 219, in _call_with_frames_removed
  File "/opt/airflow/dags/first_dag.py", line 11, in <module>
    with DAG(
TypeError: __init__() got an unexpected keyword argument 'scheduler_interval'
[2023-12-21T19:53:21.707+0000] {processor.py:842} WARNING - No viable dags retrieved from /opt/airflow/dags/first_dag.py
[2023-12-21T19:53:21.734+0000] {processor.py:183} INFO - Processing /opt/airflow/dags/first_dag.py took 0.074 seconds
[2023-12-21T19:53:25.739+0000] {processor.py:161} INFO - Started process (PID=222) to work on /opt/airflow/dags/first_dag.py
[2023-12-21T19:53:25.740+0000] {processor.py:830} INFO - Processing file /opt/airflow/dags/first_dag.py for tasks to queue
[2023-12-21T19:53:25.751+0000] {logging_mixin.py:188} INFO - [2023-12-21T19:53:25.743+0000] {dagbag.py:538} INFO - Filling up the DagBag from /opt/airflow/dags/first_dag.py
[2023-12-21T19:53:25.756+0000] {logging_mixin.py:188} INFO - [2023-12-21T19:53:25.755+0000] {dagbag.py:348} ERROR - Failed to import: /opt/airflow/dags/first_dag.py
Traceback (most recent call last):
  File "/home/airflow/.local/lib/python3.8/site-packages/airflow/models/dagbag.py", line 344, in parse
    loader.exec_module(new_module)
  File "<frozen importlib._bootstrap_external>", line 839, in exec_module
  File "<frozen importlib._bootstrap_external>", line 976, in get_code
  File "<frozen importlib._bootstrap_external>", line 906, in source_to_code
  File "<frozen importlib._bootstrap>", line 219, in _call_with_frames_removed
  File "/opt/airflow/dags/first_dag.py", line 8
    }
    ^
SyntaxError: invalid syntax
[2023-12-21T19:53:25.757+0000] {processor.py:842} WARNING - No viable dags retrieved from /opt/airflow/dags/first_dag.py
[2023-12-21T19:53:25.817+0000] {processor.py:183} INFO - Processing /opt/airflow/dags/first_dag.py took 0.091 seconds
[2023-12-21T19:53:26.800+0000] {processor.py:161} INFO - Started process (PID=223) to work on /opt/airflow/dags/first_dag.py
[2023-12-21T19:53:26.800+0000] {processor.py:830} INFO - Processing file /opt/airflow/dags/first_dag.py for tasks to queue
[2023-12-21T19:53:26.804+0000] {logging_mixin.py:188} INFO - [2023-12-21T19:53:26.803+0000] {dagbag.py:538} INFO - Filling up the DagBag from /opt/airflow/dags/first_dag.py
[2023-12-21T19:53:26.808+0000] {logging_mixin.py:188} INFO - [2023-12-21T19:53:26.807+0000] {dagbag.py:348} ERROR - Failed to import: /opt/airflow/dags/first_dag.py
Traceback (most recent call last):
  File "/home/airflow/.local/lib/python3.8/site-packages/airflow/models/dagbag.py", line 344, in parse
    loader.exec_module(new_module)
  File "<frozen importlib._bootstrap_external>", line 839, in exec_module
  File "<frozen importlib._bootstrap_external>", line 976, in get_code
  File "<frozen importlib._bootstrap_external>", line 906, in source_to_code
  File "<frozen importlib._bootstrap>", line 219, in _call_with_frames_removed
  File "/opt/airflow/dags/first_dag.py", line 8
    }
    ^
SyntaxError: invalid syntax
[2023-12-21T19:53:26.808+0000] {processor.py:842} WARNING - No viable dags retrieved from /opt/airflow/dags/first_dag.py
[2023-12-21T19:53:26.833+0000] {processor.py:183} INFO - Processing /opt/airflow/dags/first_dag.py took 0.038 seconds
[2023-12-21T19:53:30.833+0000] {processor.py:161} INFO - Started process (PID=224) to work on /opt/airflow/dags/first_dag.py
[2023-12-21T19:53:30.834+0000] {processor.py:830} INFO - Processing file /opt/airflow/dags/first_dag.py for tasks to queue
[2023-12-21T19:53:30.837+0000] {logging_mixin.py:188} INFO - [2023-12-21T19:53:30.837+0000] {dagbag.py:538} INFO - Filling up the DagBag from /opt/airflow/dags/first_dag.py
[2023-12-21T19:53:30.841+0000] {logging_mixin.py:188} INFO - [2023-12-21T19:53:30.840+0000] {dagbag.py:348} ERROR - Failed to import: /opt/airflow/dags/first_dag.py
Traceback (most recent call last):
  File "/home/airflow/.local/lib/python3.8/site-packages/airflow/models/dagbag.py", line 344, in parse
    loader.exec_module(new_module)
  File "<frozen importlib._bootstrap_external>", line 839, in exec_module
  File "<frozen importlib._bootstrap_external>", line 976, in get_code
  File "<frozen importlib._bootstrap_external>", line 906, in source_to_code
  File "<frozen importlib._bootstrap>", line 219, in _call_with_frames_removed
  File "/opt/airflow/dags/first_dag.py", line 8
    }
    ^
SyntaxError: invalid syntax
[2023-12-21T19:53:30.841+0000] {processor.py:842} WARNING - No viable dags retrieved from /opt/airflow/dags/first_dag.py
[2023-12-21T19:53:30.868+0000] {processor.py:183} INFO - Processing /opt/airflow/dags/first_dag.py took 0.038 seconds
[2023-12-21T19:53:35.942+0000] {processor.py:161} INFO - Started process (PID=225) to work on /opt/airflow/dags/first_dag.py
[2023-12-21T19:53:35.943+0000] {processor.py:830} INFO - Processing file /opt/airflow/dags/first_dag.py for tasks to queue
[2023-12-21T19:53:35.946+0000] {logging_mixin.py:188} INFO - [2023-12-21T19:53:35.946+0000] {dagbag.py:538} INFO - Filling up the DagBag from /opt/airflow/dags/first_dag.py
[2023-12-21T19:53:35.951+0000] {logging_mixin.py:188} INFO - [2023-12-21T19:53:35.950+0000] {dagbag.py:348} ERROR - Failed to import: /opt/airflow/dags/first_dag.py
Traceback (most recent call last):
  File "/home/airflow/.local/lib/python3.8/site-packages/airflow/models/dagbag.py", line 344, in parse
    loader.exec_module(new_module)
  File "<frozen importlib._bootstrap_external>", line 843, in exec_module
  File "<frozen importlib._bootstrap>", line 219, in _call_with_frames_removed
  File "/opt/airflow/dags/first_dag.py", line 11, in <module>
    with DAG(
TypeError: __init__() got an unexpected keyword argument 'scheduler_interval'
[2023-12-21T19:53:35.952+0000] {processor.py:842} WARNING - No viable dags retrieved from /opt/airflow/dags/first_dag.py
[2023-12-21T19:53:35.975+0000] {processor.py:183} INFO - Processing /opt/airflow/dags/first_dag.py took 0.039 seconds
[2023-12-21T19:53:39.042+0000] {processor.py:161} INFO - Started process (PID=226) to work on /opt/airflow/dags/first_dag.py
[2023-12-21T19:53:39.044+0000] {processor.py:830} INFO - Processing file /opt/airflow/dags/first_dag.py for tasks to queue
[2023-12-21T19:53:39.049+0000] {logging_mixin.py:188} INFO - [2023-12-21T19:53:39.048+0000] {dagbag.py:538} INFO - Filling up the DagBag from /opt/airflow/dags/first_dag.py
[2023-12-21T19:53:39.057+0000] {logging_mixin.py:188} INFO - [2023-12-21T19:53:39.056+0000] {dagbag.py:348} ERROR - Failed to import: /opt/airflow/dags/first_dag.py
Traceback (most recent call last):
  File "/home/airflow/.local/lib/python3.8/site-packages/airflow/models/dagbag.py", line 344, in parse
    loader.exec_module(new_module)
  File "<frozen importlib._bootstrap_external>", line 843, in exec_module
  File "<frozen importlib._bootstrap>", line 219, in _call_with_frames_removed
  File "/opt/airflow/dags/first_dag.py", line 11, in <module>
    with DAG(
TypeError: __init__() got an unexpected keyword argument 'scheduler_interval'
[2023-12-21T19:53:39.057+0000] {processor.py:842} WARNING - No viable dags retrieved from /opt/airflow/dags/first_dag.py
[2023-12-21T19:53:39.085+0000] {processor.py:183} INFO - Processing /opt/airflow/dags/first_dag.py took 0.055 seconds
[2023-12-21T19:53:40.075+0000] {processor.py:161} INFO - Started process (PID=227) to work on /opt/airflow/dags/first_dag.py
[2023-12-21T19:53:40.077+0000] {processor.py:830} INFO - Processing file /opt/airflow/dags/first_dag.py for tasks to queue
[2023-12-21T19:53:40.080+0000] {logging_mixin.py:188} INFO - [2023-12-21T19:53:40.080+0000] {dagbag.py:538} INFO - Filling up the DagBag from /opt/airflow/dags/first_dag.py
[2023-12-21T19:53:40.085+0000] {logging_mixin.py:188} INFO - [2023-12-21T19:53:40.084+0000] {dagbag.py:348} ERROR - Failed to import: /opt/airflow/dags/first_dag.py
Traceback (most recent call last):
  File "/home/airflow/.local/lib/python3.8/site-packages/airflow/models/dagbag.py", line 344, in parse
    loader.exec_module(new_module)
  File "<frozen importlib._bootstrap_external>", line 843, in exec_module
  File "<frozen importlib._bootstrap>", line 219, in _call_with_frames_removed
  File "/opt/airflow/dags/first_dag.py", line 11, in <module>
    with DAG(
TypeError: __init__() got an unexpected keyword argument 'scheduler_interval'
[2023-12-21T19:53:40.085+0000] {processor.py:842} WARNING - No viable dags retrieved from /opt/airflow/dags/first_dag.py
[2023-12-21T19:53:40.110+0000] {processor.py:183} INFO - Processing /opt/airflow/dags/first_dag.py took 0.041 seconds
[2023-12-21T19:53:42.126+0000] {processor.py:161} INFO - Started process (PID=228) to work on /opt/airflow/dags/first_dag.py
[2023-12-21T19:53:42.128+0000] {processor.py:830} INFO - Processing file /opt/airflow/dags/first_dag.py for tasks to queue
[2023-12-21T19:53:42.132+0000] {logging_mixin.py:188} INFO - [2023-12-21T19:53:42.132+0000] {dagbag.py:538} INFO - Filling up the DagBag from /opt/airflow/dags/first_dag.py
[2023-12-21T19:53:42.139+0000] {logging_mixin.py:188} INFO - [2023-12-21T19:53:42.138+0000] {dagbag.py:348} ERROR - Failed to import: /opt/airflow/dags/first_dag.py
Traceback (most recent call last):
  File "/home/airflow/.local/lib/python3.8/site-packages/airflow/models/dagbag.py", line 344, in parse
    loader.exec_module(new_module)
  File "<frozen importlib._bootstrap_external>", line 843, in exec_module
  File "<frozen importlib._bootstrap>", line 219, in _call_with_frames_removed
  File "/opt/airflow/dags/first_dag.py", line 11, in <module>
    with DAG(
TypeError: __init__() got an unexpected keyword argument 'scheduler_interval'
[2023-12-21T19:53:42.139+0000] {processor.py:842} WARNING - No viable dags retrieved from /opt/airflow/dags/first_dag.py
[2023-12-21T19:53:42.164+0000] {processor.py:183} INFO - Processing /opt/airflow/dags/first_dag.py took 0.043 seconds
[2023-12-21T19:53:44.161+0000] {processor.py:161} INFO - Started process (PID=229) to work on /opt/airflow/dags/first_dag.py
[2023-12-21T19:53:44.161+0000] {processor.py:830} INFO - Processing file /opt/airflow/dags/first_dag.py for tasks to queue
[2023-12-21T19:53:44.164+0000] {logging_mixin.py:188} INFO - [2023-12-21T19:53:44.164+0000] {dagbag.py:538} INFO - Filling up the DagBag from /opt/airflow/dags/first_dag.py
[2023-12-21T19:53:44.170+0000] {logging_mixin.py:188} INFO - [2023-12-21T19:53:44.169+0000] {dagbag.py:348} ERROR - Failed to import: /opt/airflow/dags/first_dag.py
Traceback (most recent call last):
  File "/home/airflow/.local/lib/python3.8/site-packages/airflow/models/dagbag.py", line 344, in parse
    loader.exec_module(new_module)
  File "<frozen importlib._bootstrap_external>", line 843, in exec_module
  File "<frozen importlib._bootstrap>", line 219, in _call_with_frames_removed
  File "/opt/airflow/dags/first_dag.py", line 11, in <module>
    with DAG(
TypeError: __init__() got an unexpected keyword argument 'scheduler_interval'
[2023-12-21T19:53:44.170+0000] {processor.py:842} WARNING - No viable dags retrieved from /opt/airflow/dags/first_dag.py
[2023-12-21T19:53:44.195+0000] {processor.py:183} INFO - Processing /opt/airflow/dags/first_dag.py took 0.039 seconds
[2023-12-21T19:53:46.209+0000] {processor.py:161} INFO - Started process (PID=230) to work on /opt/airflow/dags/first_dag.py
[2023-12-21T19:53:46.210+0000] {processor.py:830} INFO - Processing file /opt/airflow/dags/first_dag.py for tasks to queue
[2023-12-21T19:53:46.213+0000] {logging_mixin.py:188} INFO - [2023-12-21T19:53:46.213+0000] {dagbag.py:538} INFO - Filling up the DagBag from /opt/airflow/dags/first_dag.py
[2023-12-21T19:53:46.218+0000] {logging_mixin.py:188} INFO - [2023-12-21T19:53:46.217+0000] {dagbag.py:348} ERROR - Failed to import: /opt/airflow/dags/first_dag.py
Traceback (most recent call last):
  File "/home/airflow/.local/lib/python3.8/site-packages/airflow/models/dagbag.py", line 344, in parse
    loader.exec_module(new_module)
  File "<frozen importlib._bootstrap_external>", line 843, in exec_module
  File "<frozen importlib._bootstrap>", line 219, in _call_with_frames_removed
  File "/opt/airflow/dags/first_dag.py", line 11, in <module>
    with DAG(
TypeError: __init__() got an unexpected keyword argument 'scheduler_interval'
[2023-12-21T19:53:46.218+0000] {processor.py:842} WARNING - No viable dags retrieved from /opt/airflow/dags/first_dag.py
[2023-12-21T19:53:46.243+0000] {processor.py:183} INFO - Processing /opt/airflow/dags/first_dag.py took 0.038 seconds
[2023-12-21T19:53:50.299+0000] {processor.py:161} INFO - Started process (PID=231) to work on /opt/airflow/dags/first_dag.py
[2023-12-21T19:53:50.300+0000] {processor.py:830} INFO - Processing file /opt/airflow/dags/first_dag.py for tasks to queue
[2023-12-21T19:53:50.304+0000] {logging_mixin.py:188} INFO - [2023-12-21T19:53:50.304+0000] {dagbag.py:538} INFO - Filling up the DagBag from /opt/airflow/dags/first_dag.py
[2023-12-21T19:53:50.310+0000] {logging_mixin.py:188} INFO - [2023-12-21T19:53:50.309+0000] {dagbag.py:348} ERROR - Failed to import: /opt/airflow/dags/first_dag.py
Traceback (most recent call last):
  File "/home/airflow/.local/lib/python3.8/site-packages/airflow/models/dagbag.py", line 344, in parse
    loader.exec_module(new_module)
  File "<frozen importlib._bootstrap_external>", line 843, in exec_module
  File "<frozen importlib._bootstrap>", line 219, in _call_with_frames_removed
  File "/opt/airflow/dags/first_dag.py", line 11, in <module>
    with DAG(
TypeError: __init__() got an unexpected keyword argument 'scheduler_interval'
[2023-12-21T19:53:50.311+0000] {processor.py:842} WARNING - No viable dags retrieved from /opt/airflow/dags/first_dag.py
[2023-12-21T19:53:50.343+0000] {processor.py:183} INFO - Processing /opt/airflow/dags/first_dag.py took 0.050 seconds
[2023-12-21T19:53:51.335+0000] {processor.py:161} INFO - Started process (PID=232) to work on /opt/airflow/dags/first_dag.py
[2023-12-21T19:53:51.336+0000] {processor.py:830} INFO - Processing file /opt/airflow/dags/first_dag.py for tasks to queue
[2023-12-21T19:53:51.339+0000] {logging_mixin.py:188} INFO - [2023-12-21T19:53:51.339+0000] {dagbag.py:538} INFO - Filling up the DagBag from /opt/airflow/dags/first_dag.py
[2023-12-21T19:53:51.343+0000] {logging_mixin.py:188} INFO - [2023-12-21T19:53:51.342+0000] {dagbag.py:348} ERROR - Failed to import: /opt/airflow/dags/first_dag.py
Traceback (most recent call last):
  File "/home/airflow/.local/lib/python3.8/site-packages/airflow/models/dagbag.py", line 344, in parse
    loader.exec_module(new_module)
  File "<frozen importlib._bootstrap_external>", line 843, in exec_module
  File "<frozen importlib._bootstrap>", line 219, in _call_with_frames_removed
  File "/opt/airflow/dags/first_dag.py", line 12, in <module>
    with DAG(
TypeError: __init__() got an unexpected keyword argument 'scheduler_interval'
[2023-12-21T19:53:51.344+0000] {processor.py:842} WARNING - No viable dags retrieved from /opt/airflow/dags/first_dag.py
[2023-12-21T19:53:51.370+0000] {processor.py:183} INFO - Processing /opt/airflow/dags/first_dag.py took 0.040 seconds
[2023-12-21T19:53:53.414+0000] {processor.py:161} INFO - Started process (PID=238) to work on /opt/airflow/dags/first_dag.py
[2023-12-21T19:53:53.429+0000] {processor.py:830} INFO - Processing file /opt/airflow/dags/first_dag.py for tasks to queue
[2023-12-21T19:53:53.440+0000] {logging_mixin.py:188} INFO - [2023-12-21T19:53:53.440+0000] {dagbag.py:538} INFO - Filling up the DagBag from /opt/airflow/dags/first_dag.py
[2023-12-21T19:53:53.446+0000] {logging_mixin.py:188} INFO - [2023-12-21T19:53:53.445+0000] {dagbag.py:348} ERROR - Failed to import: /opt/airflow/dags/first_dag.py
Traceback (most recent call last):
  File "/home/airflow/.local/lib/python3.8/site-packages/airflow/models/dagbag.py", line 344, in parse
    loader.exec_module(new_module)
  File "<frozen importlib._bootstrap_external>", line 843, in exec_module
  File "<frozen importlib._bootstrap>", line 219, in _call_with_frames_removed
  File "/opt/airflow/dags/first_dag.py", line 11, in <module>
    with DAG(
TypeError: __init__() got an unexpected keyword argument 'scheduler_interval'
[2023-12-21T19:53:53.447+0000] {processor.py:842} WARNING - No viable dags retrieved from /opt/airflow/dags/first_dag.py
[2023-12-21T19:53:53.488+0000] {processor.py:183} INFO - Processing /opt/airflow/dags/first_dag.py took 0.080 seconds
[2023-12-21T19:53:55.502+0000] {processor.py:161} INFO - Started process (PID=239) to work on /opt/airflow/dags/first_dag.py
[2023-12-21T19:53:55.503+0000] {processor.py:830} INFO - Processing file /opt/airflow/dags/first_dag.py for tasks to queue
[2023-12-21T19:53:55.506+0000] {logging_mixin.py:188} INFO - [2023-12-21T19:53:55.506+0000] {dagbag.py:538} INFO - Filling up the DagBag from /opt/airflow/dags/first_dag.py
[2023-12-21T19:53:55.510+0000] {logging_mixin.py:188} INFO - [2023-12-21T19:53:55.509+0000] {dagbag.py:348} ERROR - Failed to import: /opt/airflow/dags/first_dag.py
Traceback (most recent call last):
  File "/home/airflow/.local/lib/python3.8/site-packages/airflow/models/dagbag.py", line 344, in parse
    loader.exec_module(new_module)
  File "<frozen importlib._bootstrap_external>", line 843, in exec_module
  File "<frozen importlib._bootstrap>", line 219, in _call_with_frames_removed
  File "/opt/airflow/dags/first_dag.py", line 11, in <module>
    with DAG(
TypeError: __init__() got an unexpected keyword argument 'scheduler_interval'
[2023-12-21T19:53:55.511+0000] {processor.py:842} WARNING - No viable dags retrieved from /opt/airflow/dags/first_dag.py
[2023-12-21T19:53:55.535+0000] {processor.py:183} INFO - Processing /opt/airflow/dags/first_dag.py took 0.039 seconds
[2023-12-21T19:54:10.627+0000] {processor.py:161} INFO - Started process (PID=240) to work on /opt/airflow/dags/first_dag.py
[2023-12-21T19:54:10.629+0000] {processor.py:830} INFO - Processing file /opt/airflow/dags/first_dag.py for tasks to queue
[2023-12-21T19:54:10.632+0000] {logging_mixin.py:188} INFO - [2023-12-21T19:54:10.631+0000] {dagbag.py:538} INFO - Filling up the DagBag from /opt/airflow/dags/first_dag.py
[2023-12-21T19:54:10.637+0000] {logging_mixin.py:188} INFO - [2023-12-21T19:54:10.636+0000] {dagbag.py:348} ERROR - Failed to import: /opt/airflow/dags/first_dag.py
Traceback (most recent call last):
  File "/home/airflow/.local/lib/python3.8/site-packages/airflow/models/dagbag.py", line 344, in parse
    loader.exec_module(new_module)
  File "<frozen importlib._bootstrap_external>", line 843, in exec_module
  File "<frozen importlib._bootstrap>", line 219, in _call_with_frames_removed
  File "/opt/airflow/dags/first_dag.py", line 11, in <module>
    with DAG(
TypeError: __init__() got an unexpected keyword argument 'scheduler_interval'
[2023-12-21T19:54:10.638+0000] {processor.py:842} WARNING - No viable dags retrieved from /opt/airflow/dags/first_dag.py
[2023-12-21T19:54:10.663+0000] {processor.py:183} INFO - Processing /opt/airflow/dags/first_dag.py took 0.042 seconds
[2023-12-21T19:54:15.750+0000] {processor.py:161} INFO - Started process (PID=241) to work on /opt/airflow/dags/first_dag.py
[2023-12-21T19:54:15.754+0000] {processor.py:830} INFO - Processing file /opt/airflow/dags/first_dag.py for tasks to queue
[2023-12-21T19:54:15.765+0000] {logging_mixin.py:188} INFO - [2023-12-21T19:54:15.763+0000] {dagbag.py:538} INFO - Filling up the DagBag from /opt/airflow/dags/first_dag.py
[2023-12-21T19:54:15.780+0000] {logging_mixin.py:188} INFO - [2023-12-21T19:54:15.778+0000] {dagbag.py:348} ERROR - Failed to import: /opt/airflow/dags/first_dag.py
Traceback (most recent call last):
  File "/home/airflow/.local/lib/python3.8/site-packages/airflow/models/dagbag.py", line 344, in parse
    loader.exec_module(new_module)
  File "<frozen importlib._bootstrap_external>", line 843, in exec_module
  File "<frozen importlib._bootstrap>", line 219, in _call_with_frames_removed
  File "/opt/airflow/dags/first_dag.py", line 11, in <module>
    with DAG(
TypeError: __init__() got an unexpected keyword argument 'scheduler_interval'
[2023-12-21T19:54:15.781+0000] {processor.py:842} WARNING - No viable dags retrieved from /opt/airflow/dags/first_dag.py
[2023-12-21T19:54:15.827+0000] {processor.py:183} INFO - Processing /opt/airflow/dags/first_dag.py took 0.100 seconds
[2023-12-21T19:54:16.866+0000] {processor.py:161} INFO - Started process (PID=242) to work on /opt/airflow/dags/first_dag.py
[2023-12-21T19:54:16.867+0000] {processor.py:830} INFO - Processing file /opt/airflow/dags/first_dag.py for tasks to queue
[2023-12-21T19:54:16.871+0000] {logging_mixin.py:188} INFO - [2023-12-21T19:54:16.870+0000] {dagbag.py:538} INFO - Filling up the DagBag from /opt/airflow/dags/first_dag.py
[2023-12-21T19:54:16.877+0000] {logging_mixin.py:188} INFO - [2023-12-21T19:54:16.875+0000] {dagbag.py:348} ERROR - Failed to import: /opt/airflow/dags/first_dag.py
Traceback (most recent call last):
  File "/home/airflow/.local/lib/python3.8/site-packages/airflow/models/dagbag.py", line 344, in parse
    loader.exec_module(new_module)
  File "<frozen importlib._bootstrap_external>", line 843, in exec_module
  File "<frozen importlib._bootstrap>", line 219, in _call_with_frames_removed
  File "/opt/airflow/dags/first_dag.py", line 12, in <module>
    with DAG(
TypeError: __init__() got an unexpected keyword argument 'scheduler_interval'
[2023-12-21T19:54:16.877+0000] {processor.py:842} WARNING - No viable dags retrieved from /opt/airflow/dags/first_dag.py
[2023-12-21T19:54:16.901+0000] {processor.py:183} INFO - Processing /opt/airflow/dags/first_dag.py took 0.040 seconds
[2023-12-21T19:54:18.904+0000] {processor.py:161} INFO - Started process (PID=243) to work on /opt/airflow/dags/first_dag.py
[2023-12-21T19:54:18.905+0000] {processor.py:830} INFO - Processing file /opt/airflow/dags/first_dag.py for tasks to queue
[2023-12-21T19:54:18.909+0000] {logging_mixin.py:188} INFO - [2023-12-21T19:54:18.908+0000] {dagbag.py:538} INFO - Filling up the DagBag from /opt/airflow/dags/first_dag.py
[2023-12-21T19:54:18.912+0000] {logging_mixin.py:188} INFO - [2023-12-21T19:54:18.911+0000] {dagbag.py:348} ERROR - Failed to import: /opt/airflow/dags/first_dag.py
Traceback (most recent call last):
  File "/home/airflow/.local/lib/python3.8/site-packages/airflow/models/dagbag.py", line 344, in parse
    loader.exec_module(new_module)
  File "<frozen importlib._bootstrap_external>", line 839, in exec_module
  File "<frozen importlib._bootstrap_external>", line 976, in get_code
  File "<frozen importlib._bootstrap_external>", line 906, in source_to_code
  File "<frozen importlib._bootstrap>", line 219, in _call_with_frames_removed
  File "/opt/airflow/dags/first_dag.py", line 9
    }
    ^
SyntaxError: invalid syntax
[2023-12-21T19:54:18.912+0000] {processor.py:842} WARNING - No viable dags retrieved from /opt/airflow/dags/first_dag.py
[2023-12-21T19:54:18.939+0000] {processor.py:183} INFO - Processing /opt/airflow/dags/first_dag.py took 0.041 seconds
[2023-12-21T19:54:24.049+0000] {processor.py:161} INFO - Started process (PID=251) to work on /opt/airflow/dags/first_dag.py
[2023-12-21T19:54:24.057+0000] {processor.py:830} INFO - Processing file /opt/airflow/dags/first_dag.py for tasks to queue
[2023-12-21T19:54:24.061+0000] {logging_mixin.py:188} INFO - [2023-12-21T19:54:24.061+0000] {dagbag.py:538} INFO - Filling up the DagBag from /opt/airflow/dags/first_dag.py
[2023-12-21T19:54:24.065+0000] {logging_mixin.py:188} INFO - [2023-12-21T19:54:24.064+0000] {dagbag.py:348} ERROR - Failed to import: /opt/airflow/dags/first_dag.py
Traceback (most recent call last):
  File "/home/airflow/.local/lib/python3.8/site-packages/airflow/models/dagbag.py", line 344, in parse
    loader.exec_module(new_module)
  File "<frozen importlib._bootstrap_external>", line 839, in exec_module
  File "<frozen importlib._bootstrap_external>", line 976, in get_code
  File "<frozen importlib._bootstrap_external>", line 906, in source_to_code
  File "<frozen importlib._bootstrap>", line 219, in _call_with_frames_removed
  File "/opt/airflow/dags/first_dag.py", line 9
    }
    ^
SyntaxError: invalid syntax
[2023-12-21T19:54:24.065+0000] {processor.py:842} WARNING - No viable dags retrieved from /opt/airflow/dags/first_dag.py
[2023-12-21T19:54:24.089+0000] {processor.py:183} INFO - Processing /opt/airflow/dags/first_dag.py took 0.047 seconds
[2023-12-21T19:54:26.090+0000] {processor.py:161} INFO - Started process (PID=252) to work on /opt/airflow/dags/first_dag.py
[2023-12-21T19:54:26.092+0000] {processor.py:830} INFO - Processing file /opt/airflow/dags/first_dag.py for tasks to queue
[2023-12-21T19:54:26.096+0000] {logging_mixin.py:188} INFO - [2023-12-21T19:54:26.095+0000] {dagbag.py:538} INFO - Filling up the DagBag from /opt/airflow/dags/first_dag.py
[2023-12-21T19:54:26.103+0000] {logging_mixin.py:188} INFO - [2023-12-21T19:54:26.101+0000] {dagbag.py:348} ERROR - Failed to import: /opt/airflow/dags/first_dag.py
Traceback (most recent call last):
  File "/home/airflow/.local/lib/python3.8/site-packages/airflow/models/dagbag.py", line 344, in parse
    loader.exec_module(new_module)
  File "<frozen importlib._bootstrap_external>", line 839, in exec_module
  File "<frozen importlib._bootstrap_external>", line 976, in get_code
  File "<frozen importlib._bootstrap_external>", line 906, in source_to_code
  File "<frozen importlib._bootstrap>", line 219, in _call_with_frames_removed
  File "/opt/airflow/dags/first_dag.py", line 9
    }
    ^
SyntaxError: invalid syntax
[2023-12-21T19:54:26.104+0000] {processor.py:842} WARNING - No viable dags retrieved from /opt/airflow/dags/first_dag.py
[2023-12-21T19:54:26.148+0000] {processor.py:183} INFO - Processing /opt/airflow/dags/first_dag.py took 0.066 seconds
[2023-12-21T19:54:28.148+0000] {processor.py:161} INFO - Started process (PID=253) to work on /opt/airflow/dags/first_dag.py
[2023-12-21T19:54:28.150+0000] {processor.py:830} INFO - Processing file /opt/airflow/dags/first_dag.py for tasks to queue
[2023-12-21T19:54:28.154+0000] {logging_mixin.py:188} INFO - [2023-12-21T19:54:28.154+0000] {dagbag.py:538} INFO - Filling up the DagBag from /opt/airflow/dags/first_dag.py
[2023-12-21T19:54:28.159+0000] {logging_mixin.py:188} INFO - [2023-12-21T19:54:28.158+0000] {dagbag.py:348} ERROR - Failed to import: /opt/airflow/dags/first_dag.py
Traceback (most recent call last):
  File "/home/airflow/.local/lib/python3.8/site-packages/airflow/models/dagbag.py", line 344, in parse
    loader.exec_module(new_module)
  File "<frozen importlib._bootstrap_external>", line 839, in exec_module
  File "<frozen importlib._bootstrap_external>", line 976, in get_code
  File "<frozen importlib._bootstrap_external>", line 906, in source_to_code
  File "<frozen importlib._bootstrap>", line 219, in _call_with_frames_removed
  File "/opt/airflow/dags/first_dag.py", line 9
    }
    ^
SyntaxError: invalid syntax
[2023-12-21T19:54:28.160+0000] {processor.py:842} WARNING - No viable dags retrieved from /opt/airflow/dags/first_dag.py
[2023-12-21T19:54:28.192+0000] {processor.py:183} INFO - Processing /opt/airflow/dags/first_dag.py took 0.049 seconds
[2023-12-21T19:54:42.300+0000] {processor.py:161} INFO - Started process (PID=254) to work on /opt/airflow/dags/first_dag.py
[2023-12-21T19:54:42.301+0000] {processor.py:830} INFO - Processing file /opt/airflow/dags/first_dag.py for tasks to queue
[2023-12-21T19:54:42.305+0000] {logging_mixin.py:188} INFO - [2023-12-21T19:54:42.304+0000] {dagbag.py:538} INFO - Filling up the DagBag from /opt/airflow/dags/first_dag.py
[2023-12-21T19:54:42.308+0000] {logging_mixin.py:188} INFO - [2023-12-21T19:54:42.307+0000] {dagbag.py:348} ERROR - Failed to import: /opt/airflow/dags/first_dag.py
Traceback (most recent call last):
  File "/home/airflow/.local/lib/python3.8/site-packages/airflow/models/dagbag.py", line 344, in parse
    loader.exec_module(new_module)
  File "<frozen importlib._bootstrap_external>", line 839, in exec_module
  File "<frozen importlib._bootstrap_external>", line 976, in get_code
  File "<frozen importlib._bootstrap_external>", line 906, in source_to_code
  File "<frozen importlib._bootstrap>", line 219, in _call_with_frames_removed
  File "/opt/airflow/dags/first_dag.py", line 10
    }
    ^
SyntaxError: invalid syntax
[2023-12-21T19:54:42.309+0000] {processor.py:842} WARNING - No viable dags retrieved from /opt/airflow/dags/first_dag.py
[2023-12-21T19:54:42.333+0000] {processor.py:183} INFO - Processing /opt/airflow/dags/first_dag.py took 0.038 seconds
[2023-12-21T19:54:45.331+0000] {processor.py:161} INFO - Started process (PID=255) to work on /opt/airflow/dags/first_dag.py
[2023-12-21T19:54:45.332+0000] {processor.py:830} INFO - Processing file /opt/airflow/dags/first_dag.py for tasks to queue
[2023-12-21T19:54:45.336+0000] {logging_mixin.py:188} INFO - [2023-12-21T19:54:45.335+0000] {dagbag.py:538} INFO - Filling up the DagBag from /opt/airflow/dags/first_dag.py
[2023-12-21T19:54:45.340+0000] {logging_mixin.py:188} INFO - [2023-12-21T19:54:45.339+0000] {dagbag.py:348} ERROR - Failed to import: /opt/airflow/dags/first_dag.py
Traceback (most recent call last):
  File "/home/airflow/.local/lib/python3.8/site-packages/airflow/models/dagbag.py", line 344, in parse
    loader.exec_module(new_module)
  File "<frozen importlib._bootstrap_external>", line 839, in exec_module
  File "<frozen importlib._bootstrap_external>", line 976, in get_code
  File "<frozen importlib._bootstrap_external>", line 906, in source_to_code
  File "<frozen importlib._bootstrap>", line 219, in _call_with_frames_removed
  File "/opt/airflow/dags/first_dag.py", line 9
    }
    ^
SyntaxError: invalid syntax
[2023-12-21T19:54:45.340+0000] {processor.py:842} WARNING - No viable dags retrieved from /opt/airflow/dags/first_dag.py
[2023-12-21T19:54:45.363+0000] {processor.py:183} INFO - Processing /opt/airflow/dags/first_dag.py took 0.036 seconds
[2023-12-21T19:55:15.656+0000] {processor.py:161} INFO - Started process (PID=262) to work on /opt/airflow/dags/first_dag.py
[2023-12-21T19:55:15.674+0000] {processor.py:830} INFO - Processing file /opt/airflow/dags/first_dag.py for tasks to queue
[2023-12-21T19:55:15.691+0000] {logging_mixin.py:188} INFO - [2023-12-21T19:55:15.690+0000] {dagbag.py:538} INFO - Filling up the DagBag from /opt/airflow/dags/first_dag.py
[2023-12-21T19:55:15.702+0000] {logging_mixin.py:188} INFO - [2023-12-21T19:55:15.699+0000] {dagbag.py:348} ERROR - Failed to import: /opt/airflow/dags/first_dag.py
Traceback (most recent call last):
  File "/home/airflow/.local/lib/python3.8/site-packages/airflow/models/dagbag.py", line 344, in parse
    loader.exec_module(new_module)
  File "<frozen importlib._bootstrap_external>", line 839, in exec_module
  File "<frozen importlib._bootstrap_external>", line 976, in get_code
  File "<frozen importlib._bootstrap_external>", line 906, in source_to_code
  File "<frozen importlib._bootstrap>", line 219, in _call_with_frames_removed
  File "/opt/airflow/dags/first_dag.py", line 9
    }
    ^
SyntaxError: invalid syntax
[2023-12-21T19:55:15.703+0000] {processor.py:842} WARNING - No viable dags retrieved from /opt/airflow/dags/first_dag.py
[2023-12-21T19:55:15.752+0000] {processor.py:183} INFO - Processing /opt/airflow/dags/first_dag.py took 0.126 seconds
[2023-12-21T19:55:16.735+0000] {processor.py:161} INFO - Started process (PID=263) to work on /opt/airflow/dags/first_dag.py
[2023-12-21T19:55:16.736+0000] {processor.py:830} INFO - Processing file /opt/airflow/dags/first_dag.py for tasks to queue
[2023-12-21T19:55:16.741+0000] {logging_mixin.py:188} INFO - [2023-12-21T19:55:16.740+0000] {dagbag.py:538} INFO - Filling up the DagBag from /opt/airflow/dags/first_dag.py
[2023-12-21T19:55:16.746+0000] {logging_mixin.py:188} INFO - [2023-12-21T19:55:16.745+0000] {dagbag.py:348} ERROR - Failed to import: /opt/airflow/dags/first_dag.py
Traceback (most recent call last):
  File "/home/airflow/.local/lib/python3.8/site-packages/airflow/models/dagbag.py", line 344, in parse
    loader.exec_module(new_module)
  File "<frozen importlib._bootstrap_external>", line 843, in exec_module
  File "<frozen importlib._bootstrap>", line 219, in _call_with_frames_removed
  File "/opt/airflow/dags/first_dag.py", line 2, in <module>
    from datetime import datetime, timedelat
ImportError: cannot import name 'timedelat' from 'datetime' (/usr/local/lib/python3.8/datetime.py)
[2023-12-21T19:55:16.746+0000] {processor.py:842} WARNING - No viable dags retrieved from /opt/airflow/dags/first_dag.py
[2023-12-21T19:55:16.769+0000] {processor.py:183} INFO - Processing /opt/airflow/dags/first_dag.py took 0.041 seconds
[2023-12-21T19:55:20.858+0000] {processor.py:161} INFO - Started process (PID=264) to work on /opt/airflow/dags/first_dag.py
[2023-12-21T19:55:20.864+0000] {processor.py:830} INFO - Processing file /opt/airflow/dags/first_dag.py for tasks to queue
[2023-12-21T19:55:20.873+0000] {logging_mixin.py:188} INFO - [2023-12-21T19:55:20.872+0000] {dagbag.py:538} INFO - Filling up the DagBag from /opt/airflow/dags/first_dag.py
[2023-12-21T19:55:20.883+0000] {logging_mixin.py:188} INFO - [2023-12-21T19:55:20.881+0000] {dagbag.py:348} ERROR - Failed to import: /opt/airflow/dags/first_dag.py
Traceback (most recent call last):
  File "/home/airflow/.local/lib/python3.8/site-packages/airflow/models/dagbag.py", line 344, in parse
    loader.exec_module(new_module)
  File "<frozen importlib._bootstrap_external>", line 843, in exec_module
  File "<frozen importlib._bootstrap>", line 219, in _call_with_frames_removed
  File "/opt/airflow/dags/first_dag.py", line 2, in <module>
    from datetime import datetime, timedelat
ImportError: cannot import name 'timedelat' from 'datetime' (/usr/local/lib/python3.8/datetime.py)
[2023-12-21T19:55:20.884+0000] {processor.py:842} WARNING - No viable dags retrieved from /opt/airflow/dags/first_dag.py
[2023-12-21T19:55:20.914+0000] {processor.py:183} INFO - Processing /opt/airflow/dags/first_dag.py took 0.087 seconds
[2023-12-21T19:55:21.939+0000] {processor.py:161} INFO - Started process (PID=265) to work on /opt/airflow/dags/first_dag.py
[2023-12-21T19:55:21.941+0000] {processor.py:830} INFO - Processing file /opt/airflow/dags/first_dag.py for tasks to queue
[2023-12-21T19:55:21.944+0000] {logging_mixin.py:188} INFO - [2023-12-21T19:55:21.944+0000] {dagbag.py:538} INFO - Filling up the DagBag from /opt/airflow/dags/first_dag.py
[2023-12-21T19:55:21.950+0000] {logging_mixin.py:188} INFO - [2023-12-21T19:55:21.948+0000] {dagbag.py:348} ERROR - Failed to import: /opt/airflow/dags/first_dag.py
Traceback (most recent call last):
  File "/home/airflow/.local/lib/python3.8/site-packages/airflow/models/dagbag.py", line 344, in parse
    loader.exec_module(new_module)
  File "<frozen importlib._bootstrap_external>", line 843, in exec_module
  File "<frozen importlib._bootstrap>", line 219, in _call_with_frames_removed
  File "/opt/airflow/dags/first_dag.py", line 2, in <module>
    from datetime import datetime, timedelat
ImportError: cannot import name 'timedelat' from 'datetime' (/usr/local/lib/python3.8/datetime.py)
[2023-12-21T19:55:21.951+0000] {processor.py:842} WARNING - No viable dags retrieved from /opt/airflow/dags/first_dag.py
[2023-12-21T19:55:21.975+0000] {processor.py:183} INFO - Processing /opt/airflow/dags/first_dag.py took 0.046 seconds
[2023-12-21T19:55:25.082+0000] {processor.py:161} INFO - Started process (PID=272) to work on /opt/airflow/dags/first_dag.py
[2023-12-21T19:55:25.083+0000] {processor.py:830} INFO - Processing file /opt/airflow/dags/first_dag.py for tasks to queue
[2023-12-21T19:55:25.088+0000] {logging_mixin.py:188} INFO - [2023-12-21T19:55:25.088+0000] {dagbag.py:538} INFO - Filling up the DagBag from /opt/airflow/dags/first_dag.py
[2023-12-21T19:55:25.096+0000] {logging_mixin.py:188} INFO - [2023-12-21T19:55:25.094+0000] {dagbag.py:348} ERROR - Failed to import: /opt/airflow/dags/first_dag.py
Traceback (most recent call last):
  File "/home/airflow/.local/lib/python3.8/site-packages/airflow/models/dagbag.py", line 344, in parse
    loader.exec_module(new_module)
  File "<frozen importlib._bootstrap_external>", line 843, in exec_module
  File "<frozen importlib._bootstrap>", line 219, in _call_with_frames_removed
  File "/opt/airflow/dags/first_dag.py", line 2, in <module>
    from datetime import datetime, timedelat
ImportError: cannot import name 'timedelat' from 'datetime' (/usr/local/lib/python3.8/datetime.py)
[2023-12-21T19:55:25.097+0000] {processor.py:842} WARNING - No viable dags retrieved from /opt/airflow/dags/first_dag.py
[2023-12-21T19:55:25.131+0000] {processor.py:183} INFO - Processing /opt/airflow/dags/first_dag.py took 0.060 seconds
[2023-12-21T19:55:30.188+0000] {processor.py:161} INFO - Started process (PID=273) to work on /opt/airflow/dags/first_dag.py
[2023-12-21T19:55:30.189+0000] {processor.py:830} INFO - Processing file /opt/airflow/dags/first_dag.py for tasks to queue
[2023-12-21T19:55:30.194+0000] {logging_mixin.py:188} INFO - [2023-12-21T19:55:30.194+0000] {dagbag.py:538} INFO - Filling up the DagBag from /opt/airflow/dags/first_dag.py
[2023-12-21T19:55:30.201+0000] {logging_mixin.py:188} INFO - [2023-12-21T19:55:30.199+0000] {dagbag.py:348} ERROR - Failed to import: /opt/airflow/dags/first_dag.py
Traceback (most recent call last):
  File "/home/airflow/.local/lib/python3.8/site-packages/airflow/models/dagbag.py", line 344, in parse
    loader.exec_module(new_module)
  File "<frozen importlib._bootstrap_external>", line 843, in exec_module
  File "<frozen importlib._bootstrap>", line 219, in _call_with_frames_removed
  File "/opt/airflow/dags/first_dag.py", line 2, in <module>
    from datetime import datetime, timedelat
ImportError: cannot import name 'timedelat' from 'datetime' (/usr/local/lib/python3.8/datetime.py)
[2023-12-21T19:55:30.201+0000] {processor.py:842} WARNING - No viable dags retrieved from /opt/airflow/dags/first_dag.py
[2023-12-21T19:55:30.230+0000] {processor.py:183} INFO - Processing /opt/airflow/dags/first_dag.py took 0.049 seconds
[2023-12-21T19:55:32.238+0000] {processor.py:161} INFO - Started process (PID=274) to work on /opt/airflow/dags/first_dag.py
[2023-12-21T19:55:32.239+0000] {processor.py:830} INFO - Processing file /opt/airflow/dags/first_dag.py for tasks to queue
[2023-12-21T19:55:32.245+0000] {logging_mixin.py:188} INFO - [2023-12-21T19:55:32.244+0000] {dagbag.py:538} INFO - Filling up the DagBag from /opt/airflow/dags/first_dag.py
[2023-12-21T19:55:32.257+0000] {logging_mixin.py:188} INFO - [2023-12-21T19:55:32.254+0000] {dagbag.py:348} ERROR - Failed to import: /opt/airflow/dags/first_dag.py
Traceback (most recent call last):
  File "/home/airflow/.local/lib/python3.8/site-packages/airflow/models/dagbag.py", line 344, in parse
    loader.exec_module(new_module)
  File "<frozen importlib._bootstrap_external>", line 843, in exec_module
  File "<frozen importlib._bootstrap>", line 219, in _call_with_frames_removed
  File "/opt/airflow/dags/first_dag.py", line 2, in <module>
    from datetime import datetime, timedelat
ImportError: cannot import name 'timedelat' from 'datetime' (/usr/local/lib/python3.8/datetime.py)
[2023-12-21T19:55:32.258+0000] {processor.py:842} WARNING - No viable dags retrieved from /opt/airflow/dags/first_dag.py
[2023-12-21T19:55:32.308+0000] {processor.py:183} INFO - Processing /opt/airflow/dags/first_dag.py took 0.081 seconds
[2023-12-21T19:55:34.332+0000] {processor.py:161} INFO - Started process (PID=275) to work on /opt/airflow/dags/first_dag.py
[2023-12-21T19:55:34.334+0000] {processor.py:830} INFO - Processing file /opt/airflow/dags/first_dag.py for tasks to queue
[2023-12-21T19:55:34.338+0000] {logging_mixin.py:188} INFO - [2023-12-21T19:55:34.338+0000] {dagbag.py:538} INFO - Filling up the DagBag from /opt/airflow/dags/first_dag.py
[2023-12-21T19:55:34.345+0000] {logging_mixin.py:188} INFO - [2023-12-21T19:55:34.343+0000] {dagbag.py:348} ERROR - Failed to import: /opt/airflow/dags/first_dag.py
Traceback (most recent call last):
  File "/home/airflow/.local/lib/python3.8/site-packages/airflow/models/dagbag.py", line 344, in parse
    loader.exec_module(new_module)
  File "<frozen importlib._bootstrap_external>", line 843, in exec_module
  File "<frozen importlib._bootstrap>", line 219, in _call_with_frames_removed
  File "/opt/airflow/dags/first_dag.py", line 2, in <module>
    from datetime import datetime, timedelat
ImportError: cannot import name 'timedelat' from 'datetime' (/usr/local/lib/python3.8/datetime.py)
[2023-12-21T19:55:34.345+0000] {processor.py:842} WARNING - No viable dags retrieved from /opt/airflow/dags/first_dag.py
[2023-12-21T19:55:34.373+0000] {processor.py:183} INFO - Processing /opt/airflow/dags/first_dag.py took 0.048 seconds
[2023-12-21T19:55:36.374+0000] {processor.py:161} INFO - Started process (PID=276) to work on /opt/airflow/dags/first_dag.py
[2023-12-21T19:55:36.375+0000] {processor.py:830} INFO - Processing file /opt/airflow/dags/first_dag.py for tasks to queue
[2023-12-21T19:55:36.378+0000] {logging_mixin.py:188} INFO - [2023-12-21T19:55:36.377+0000] {dagbag.py:538} INFO - Filling up the DagBag from /opt/airflow/dags/first_dag.py
[2023-12-21T19:55:36.383+0000] {logging_mixin.py:188} INFO - [2023-12-21T19:55:36.382+0000] {dagbag.py:348} ERROR - Failed to import: /opt/airflow/dags/first_dag.py
Traceback (most recent call last):
  File "/home/airflow/.local/lib/python3.8/site-packages/airflow/models/dagbag.py", line 344, in parse
    loader.exec_module(new_module)
  File "<frozen importlib._bootstrap_external>", line 843, in exec_module
  File "<frozen importlib._bootstrap>", line 219, in _call_with_frames_removed
  File "/opt/airflow/dags/first_dag.py", line 2, in <module>
    from datetime import datetime, timedelat
ImportError: cannot import name 'timedelat' from 'datetime' (/usr/local/lib/python3.8/datetime.py)
[2023-12-21T19:55:36.384+0000] {processor.py:842} WARNING - No viable dags retrieved from /opt/airflow/dags/first_dag.py
[2023-12-21T19:55:36.409+0000] {processor.py:183} INFO - Processing /opt/airflow/dags/first_dag.py took 0.039 seconds
[2023-12-21T19:55:39.443+0000] {processor.py:161} INFO - Started process (PID=277) to work on /opt/airflow/dags/first_dag.py
[2023-12-21T19:55:39.444+0000] {processor.py:830} INFO - Processing file /opt/airflow/dags/first_dag.py for tasks to queue
[2023-12-21T19:55:39.449+0000] {logging_mixin.py:188} INFO - [2023-12-21T19:55:39.448+0000] {dagbag.py:538} INFO - Filling up the DagBag from /opt/airflow/dags/first_dag.py
[2023-12-21T19:55:39.454+0000] {logging_mixin.py:188} INFO - [2023-12-21T19:55:39.453+0000] {dagbag.py:348} ERROR - Failed to import: /opt/airflow/dags/first_dag.py
Traceback (most recent call last):
  File "/home/airflow/.local/lib/python3.8/site-packages/airflow/models/dagbag.py", line 344, in parse
    loader.exec_module(new_module)
  File "<frozen importlib._bootstrap_external>", line 843, in exec_module
  File "<frozen importlib._bootstrap>", line 219, in _call_with_frames_removed
  File "/opt/airflow/dags/first_dag.py", line 2, in <module>
    from datetime import datetime, timedelat
ImportError: cannot import name 'timedelat' from 'datetime' (/usr/local/lib/python3.8/datetime.py)
[2023-12-21T19:55:39.455+0000] {processor.py:842} WARNING - No viable dags retrieved from /opt/airflow/dags/first_dag.py
[2023-12-21T19:55:39.479+0000] {processor.py:183} INFO - Processing /opt/airflow/dags/first_dag.py took 0.041 seconds
[2023-12-21T19:55:44.500+0000] {processor.py:161} INFO - Started process (PID=278) to work on /opt/airflow/dags/first_dag.py
[2023-12-21T19:55:44.501+0000] {processor.py:830} INFO - Processing file /opt/airflow/dags/first_dag.py for tasks to queue
[2023-12-21T19:55:44.504+0000] {logging_mixin.py:188} INFO - [2023-12-21T19:55:44.503+0000] {dagbag.py:538} INFO - Filling up the DagBag from /opt/airflow/dags/first_dag.py
[2023-12-21T19:55:44.509+0000] {logging_mixin.py:188} INFO - [2023-12-21T19:55:44.507+0000] {dagbag.py:348} ERROR - Failed to import: /opt/airflow/dags/first_dag.py
Traceback (most recent call last):
  File "/home/airflow/.local/lib/python3.8/site-packages/airflow/models/dagbag.py", line 344, in parse
    loader.exec_module(new_module)
  File "<frozen importlib._bootstrap_external>", line 843, in exec_module
  File "<frozen importlib._bootstrap>", line 219, in _call_with_frames_removed
  File "/opt/airflow/dags/first_dag.py", line 2, in <module>
    from datetime import datetime, timedelat
ImportError: cannot import name 'timedelat' from 'datetime' (/usr/local/lib/python3.8/datetime.py)
[2023-12-21T19:55:44.509+0000] {processor.py:842} WARNING - No viable dags retrieved from /opt/airflow/dags/first_dag.py
[2023-12-21T19:55:44.534+0000] {processor.py:183} INFO - Processing /opt/airflow/dags/first_dag.py took 0.039 seconds
[2023-12-21T19:56:14.788+0000] {processor.py:161} INFO - Started process (PID=285) to work on /opt/airflow/dags/first_dag.py
[2023-12-21T19:56:14.796+0000] {processor.py:830} INFO - Processing file /opt/airflow/dags/first_dag.py for tasks to queue
[2023-12-21T19:56:14.799+0000] {logging_mixin.py:188} INFO - [2023-12-21T19:56:14.798+0000] {dagbag.py:538} INFO - Filling up the DagBag from /opt/airflow/dags/first_dag.py
[2023-12-21T19:56:14.803+0000] {logging_mixin.py:188} INFO - [2023-12-21T19:56:14.802+0000] {dagbag.py:348} ERROR - Failed to import: /opt/airflow/dags/first_dag.py
Traceback (most recent call last):
  File "/home/airflow/.local/lib/python3.8/site-packages/airflow/models/dagbag.py", line 344, in parse
    loader.exec_module(new_module)
  File "<frozen importlib._bootstrap_external>", line 843, in exec_module
  File "<frozen importlib._bootstrap>", line 219, in _call_with_frames_removed
  File "/opt/airflow/dags/first_dag.py", line 2, in <module>
    from datetime import datetime, timedelat
ImportError: cannot import name 'timedelat' from 'datetime' (/usr/local/lib/python3.8/datetime.py)
[2023-12-21T19:56:14.803+0000] {processor.py:842} WARNING - No viable dags retrieved from /opt/airflow/dags/first_dag.py
[2023-12-21T19:56:14.824+0000] {processor.py:183} INFO - Processing /opt/airflow/dags/first_dag.py took 0.044 seconds
[2023-12-21T19:56:44.999+0000] {processor.py:161} INFO - Started process (PID=292) to work on /opt/airflow/dags/first_dag.py
[2023-12-21T19:56:45.000+0000] {processor.py:830} INFO - Processing file /opt/airflow/dags/first_dag.py for tasks to queue
[2023-12-21T19:56:45.004+0000] {logging_mixin.py:188} INFO - [2023-12-21T19:56:45.003+0000] {dagbag.py:538} INFO - Filling up the DagBag from /opt/airflow/dags/first_dag.py
[2023-12-21T19:56:45.009+0000] {logging_mixin.py:188} INFO - [2023-12-21T19:56:45.008+0000] {dagbag.py:348} ERROR - Failed to import: /opt/airflow/dags/first_dag.py
Traceback (most recent call last):
  File "/home/airflow/.local/lib/python3.8/site-packages/airflow/models/dagbag.py", line 344, in parse
    loader.exec_module(new_module)
  File "<frozen importlib._bootstrap_external>", line 843, in exec_module
  File "<frozen importlib._bootstrap>", line 219, in _call_with_frames_removed
  File "/opt/airflow/dags/first_dag.py", line 2, in <module>
    from datetime import datetime, timedelat
ImportError: cannot import name 'timedelat' from 'datetime' (/usr/local/lib/python3.8/datetime.py)
[2023-12-21T19:56:45.010+0000] {processor.py:842} WARNING - No viable dags retrieved from /opt/airflow/dags/first_dag.py
[2023-12-21T19:56:45.037+0000] {processor.py:183} INFO - Processing /opt/airflow/dags/first_dag.py took 0.043 seconds
[2023-12-21T19:56:49.035+0000] {processor.py:161} INFO - Started process (PID=293) to work on /opt/airflow/dags/first_dag.py
[2023-12-21T19:56:49.037+0000] {processor.py:830} INFO - Processing file /opt/airflow/dags/first_dag.py for tasks to queue
[2023-12-21T19:56:49.040+0000] {logging_mixin.py:188} INFO - [2023-12-21T19:56:49.039+0000] {dagbag.py:538} INFO - Filling up the DagBag from /opt/airflow/dags/first_dag.py
[2023-12-21T19:56:49.045+0000] {logging_mixin.py:188} INFO - [2023-12-21T19:56:49.043+0000] {dagbag.py:348} ERROR - Failed to import: /opt/airflow/dags/first_dag.py
Traceback (most recent call last):
  File "/home/airflow/.local/lib/python3.8/site-packages/airflow/models/dagbag.py", line 344, in parse
    loader.exec_module(new_module)
  File "<frozen importlib._bootstrap_external>", line 839, in exec_module
  File "<frozen importlib._bootstrap_external>", line 976, in get_code
  File "<frozen importlib._bootstrap_external>", line 906, in source_to_code
  File "<frozen importlib._bootstrap>", line 219, in _call_with_frames_removed
  File "/opt/airflow/dags/first_dag.py", line 16
    start_date=datetime(2023, 12, 20, 13),  # Starting date of the date; at 13 or 1pm
    ^
SyntaxError: invalid syntax
[2023-12-21T19:56:49.045+0000] {processor.py:842} WARNING - No viable dags retrieved from /opt/airflow/dags/first_dag.py
[2023-12-21T19:56:49.070+0000] {processor.py:183} INFO - Processing /opt/airflow/dags/first_dag.py took 0.040 seconds
[2023-12-21T19:56:52.103+0000] {processor.py:161} INFO - Started process (PID=294) to work on /opt/airflow/dags/first_dag.py
[2023-12-21T19:56:52.104+0000] {processor.py:830} INFO - Processing file /opt/airflow/dags/first_dag.py for tasks to queue
[2023-12-21T19:56:52.109+0000] {logging_mixin.py:188} INFO - [2023-12-21T19:56:52.108+0000] {dagbag.py:538} INFO - Filling up the DagBag from /opt/airflow/dags/first_dag.py
[2023-12-21T19:56:52.113+0000] {logging_mixin.py:188} INFO - [2023-12-21T19:56:52.112+0000] {dagbag.py:348} ERROR - Failed to import: /opt/airflow/dags/first_dag.py
Traceback (most recent call last):
  File "/home/airflow/.local/lib/python3.8/site-packages/airflow/models/dagbag.py", line 344, in parse
    loader.exec_module(new_module)
  File "<frozen importlib._bootstrap_external>", line 839, in exec_module
  File "<frozen importlib._bootstrap_external>", line 976, in get_code
  File "<frozen importlib._bootstrap_external>", line 906, in source_to_code
  File "<frozen importlib._bootstrap>", line 219, in _call_with_frames_removed
  File "/opt/airflow/dags/first_dag.py", line 16
    start_date=datetime(2023, 12, 20, 13),  # Starting date of the date; at 13 or 1pm
              ^
SyntaxError: invalid syntax
[2023-12-21T19:56:52.114+0000] {processor.py:842} WARNING - No viable dags retrieved from /opt/airflow/dags/first_dag.py
[2023-12-21T19:56:52.141+0000] {processor.py:183} INFO - Processing /opt/airflow/dags/first_dag.py took 0.045 seconds
[2023-12-21T19:56:57.150+0000] {processor.py:161} INFO - Started process (PID=300) to work on /opt/airflow/dags/first_dag.py
[2023-12-21T19:56:57.151+0000] {processor.py:830} INFO - Processing file /opt/airflow/dags/first_dag.py for tasks to queue
[2023-12-21T19:56:57.154+0000] {logging_mixin.py:188} INFO - [2023-12-21T19:56:57.154+0000] {dagbag.py:538} INFO - Filling up the DagBag from /opt/airflow/dags/first_dag.py
[2023-12-21T19:56:57.159+0000] {logging_mixin.py:188} INFO - [2023-12-21T19:56:57.158+0000] {dagbag.py:348} ERROR - Failed to import: /opt/airflow/dags/first_dag.py
Traceback (most recent call last):
  File "/home/airflow/.local/lib/python3.8/site-packages/airflow/models/dagbag.py", line 344, in parse
    loader.exec_module(new_module)
  File "<frozen importlib._bootstrap_external>", line 843, in exec_module
  File "<frozen importlib._bootstrap>", line 219, in _call_with_frames_removed
  File "/opt/airflow/dags/first_dag.py", line 2, in <module>
    from datetime import datetime, timedelat
ImportError: cannot import name 'timedelat' from 'datetime' (/usr/local/lib/python3.8/datetime.py)
[2023-12-21T19:56:57.160+0000] {processor.py:842} WARNING - No viable dags retrieved from /opt/airflow/dags/first_dag.py
[2023-12-21T19:56:57.191+0000] {processor.py:183} INFO - Processing /opt/airflow/dags/first_dag.py took 0.045 seconds
[2023-12-21T19:57:27.462+0000] {processor.py:161} INFO - Started process (PID=307) to work on /opt/airflow/dags/first_dag.py
[2023-12-21T19:57:27.470+0000] {processor.py:830} INFO - Processing file /opt/airflow/dags/first_dag.py for tasks to queue
[2023-12-21T19:57:27.474+0000] {logging_mixin.py:188} INFO - [2023-12-21T19:57:27.473+0000] {dagbag.py:538} INFO - Filling up the DagBag from /opt/airflow/dags/first_dag.py
[2023-12-21T19:57:27.479+0000] {logging_mixin.py:188} INFO - [2023-12-21T19:57:27.478+0000] {dagbag.py:348} ERROR - Failed to import: /opt/airflow/dags/first_dag.py
Traceback (most recent call last):
  File "/home/airflow/.local/lib/python3.8/site-packages/airflow/models/dagbag.py", line 344, in parse
    loader.exec_module(new_module)
  File "<frozen importlib._bootstrap_external>", line 843, in exec_module
  File "<frozen importlib._bootstrap>", line 219, in _call_with_frames_removed
  File "/opt/airflow/dags/first_dag.py", line 2, in <module>
    from datetime import datetime, timedelat
ImportError: cannot import name 'timedelat' from 'datetime' (/usr/local/lib/python3.8/datetime.py)
[2023-12-21T19:57:27.480+0000] {processor.py:842} WARNING - No viable dags retrieved from /opt/airflow/dags/first_dag.py
[2023-12-21T19:57:27.518+0000] {processor.py:183} INFO - Processing /opt/airflow/dags/first_dag.py took 0.066 seconds
[2023-12-21T19:57:57.828+0000] {processor.py:161} INFO - Started process (PID=314) to work on /opt/airflow/dags/first_dag.py
[2023-12-21T19:57:57.829+0000] {processor.py:830} INFO - Processing file /opt/airflow/dags/first_dag.py for tasks to queue
[2023-12-21T19:57:57.832+0000] {logging_mixin.py:188} INFO - [2023-12-21T19:57:57.832+0000] {dagbag.py:538} INFO - Filling up the DagBag from /opt/airflow/dags/first_dag.py
[2023-12-21T19:57:57.837+0000] {logging_mixin.py:188} INFO - [2023-12-21T19:57:57.835+0000] {dagbag.py:348} ERROR - Failed to import: /opt/airflow/dags/first_dag.py
Traceback (most recent call last):
  File "/home/airflow/.local/lib/python3.8/site-packages/airflow/models/dagbag.py", line 344, in parse
    loader.exec_module(new_module)
  File "<frozen importlib._bootstrap_external>", line 843, in exec_module
  File "<frozen importlib._bootstrap>", line 219, in _call_with_frames_removed
  File "/opt/airflow/dags/first_dag.py", line 2, in <module>
    from datetime import datetime, timedelat
ImportError: cannot import name 'timedelat' from 'datetime' (/usr/local/lib/python3.8/datetime.py)
[2023-12-21T19:57:57.838+0000] {processor.py:842} WARNING - No viable dags retrieved from /opt/airflow/dags/first_dag.py
[2023-12-21T19:57:57.869+0000] {processor.py:183} INFO - Processing /opt/airflow/dags/first_dag.py took 0.050 seconds
[2023-12-21T19:58:28.088+0000] {processor.py:161} INFO - Started process (PID=321) to work on /opt/airflow/dags/first_dag.py
[2023-12-21T19:58:28.090+0000] {processor.py:830} INFO - Processing file /opt/airflow/dags/first_dag.py for tasks to queue
[2023-12-21T19:58:28.094+0000] {logging_mixin.py:188} INFO - [2023-12-21T19:58:28.093+0000] {dagbag.py:538} INFO - Filling up the DagBag from /opt/airflow/dags/first_dag.py
[2023-12-21T19:58:28.100+0000] {logging_mixin.py:188} INFO - [2023-12-21T19:58:28.097+0000] {dagbag.py:348} ERROR - Failed to import: /opt/airflow/dags/first_dag.py
Traceback (most recent call last):
  File "/home/airflow/.local/lib/python3.8/site-packages/airflow/models/dagbag.py", line 344, in parse
    loader.exec_module(new_module)
  File "<frozen importlib._bootstrap_external>", line 843, in exec_module
  File "<frozen importlib._bootstrap>", line 219, in _call_with_frames_removed
  File "/opt/airflow/dags/first_dag.py", line 2, in <module>
    from datetime import datetime, timedelat
ImportError: cannot import name 'timedelat' from 'datetime' (/usr/local/lib/python3.8/datetime.py)
[2023-12-21T19:58:28.101+0000] {processor.py:842} WARNING - No viable dags retrieved from /opt/airflow/dags/first_dag.py
[2023-12-21T19:58:28.142+0000] {processor.py:183} INFO - Processing /opt/airflow/dags/first_dag.py took 0.060 seconds
[2023-12-21T19:58:58.361+0000] {processor.py:161} INFO - Started process (PID=328) to work on /opt/airflow/dags/first_dag.py
[2023-12-21T19:58:58.362+0000] {processor.py:830} INFO - Processing file /opt/airflow/dags/first_dag.py for tasks to queue
[2023-12-21T19:58:58.366+0000] {logging_mixin.py:188} INFO - [2023-12-21T19:58:58.365+0000] {dagbag.py:538} INFO - Filling up the DagBag from /opt/airflow/dags/first_dag.py
[2023-12-21T19:58:58.371+0000] {logging_mixin.py:188} INFO - [2023-12-21T19:58:58.370+0000] {dagbag.py:348} ERROR - Failed to import: /opt/airflow/dags/first_dag.py
Traceback (most recent call last):
  File "/home/airflow/.local/lib/python3.8/site-packages/airflow/models/dagbag.py", line 344, in parse
    loader.exec_module(new_module)
  File "<frozen importlib._bootstrap_external>", line 843, in exec_module
  File "<frozen importlib._bootstrap>", line 219, in _call_with_frames_removed
  File "/opt/airflow/dags/first_dag.py", line 2, in <module>
    from datetime import datetime, timedelat
ImportError: cannot import name 'timedelat' from 'datetime' (/usr/local/lib/python3.8/datetime.py)
[2023-12-21T19:58:58.372+0000] {processor.py:842} WARNING - No viable dags retrieved from /opt/airflow/dags/first_dag.py
[2023-12-21T19:58:58.403+0000] {processor.py:183} INFO - Processing /opt/airflow/dags/first_dag.py took 0.048 seconds
[2023-12-21T19:59:28.679+0000] {processor.py:161} INFO - Started process (PID=335) to work on /opt/airflow/dags/first_dag.py
[2023-12-21T19:59:28.687+0000] {processor.py:830} INFO - Processing file /opt/airflow/dags/first_dag.py for tasks to queue
[2023-12-21T19:59:28.692+0000] {logging_mixin.py:188} INFO - [2023-12-21T19:59:28.691+0000] {dagbag.py:538} INFO - Filling up the DagBag from /opt/airflow/dags/first_dag.py
[2023-12-21T19:59:28.696+0000] {logging_mixin.py:188} INFO - [2023-12-21T19:59:28.695+0000] {dagbag.py:348} ERROR - Failed to import: /opt/airflow/dags/first_dag.py
Traceback (most recent call last):
  File "/home/airflow/.local/lib/python3.8/site-packages/airflow/models/dagbag.py", line 344, in parse
    loader.exec_module(new_module)
  File "<frozen importlib._bootstrap_external>", line 843, in exec_module
  File "<frozen importlib._bootstrap>", line 219, in _call_with_frames_removed
  File "/opt/airflow/dags/first_dag.py", line 2, in <module>
    from datetime import datetime, timedelat
ImportError: cannot import name 'timedelat' from 'datetime' (/usr/local/lib/python3.8/datetime.py)
[2023-12-21T19:59:28.696+0000] {processor.py:842} WARNING - No viable dags retrieved from /opt/airflow/dags/first_dag.py
[2023-12-21T19:59:28.725+0000] {processor.py:183} INFO - Processing /opt/airflow/dags/first_dag.py took 0.053 seconds
[2023-12-21T19:59:58.942+0000] {processor.py:161} INFO - Started process (PID=341) to work on /opt/airflow/dags/first_dag.py
[2023-12-21T19:59:58.943+0000] {processor.py:830} INFO - Processing file /opt/airflow/dags/first_dag.py for tasks to queue
[2023-12-21T19:59:58.947+0000] {logging_mixin.py:188} INFO - [2023-12-21T19:59:58.946+0000] {dagbag.py:538} INFO - Filling up the DagBag from /opt/airflow/dags/first_dag.py
[2023-12-21T19:59:58.953+0000] {logging_mixin.py:188} INFO - [2023-12-21T19:59:58.952+0000] {dagbag.py:348} ERROR - Failed to import: /opt/airflow/dags/first_dag.py
Traceback (most recent call last):
  File "/home/airflow/.local/lib/python3.8/site-packages/airflow/models/dagbag.py", line 344, in parse
    loader.exec_module(new_module)
  File "<frozen importlib._bootstrap_external>", line 843, in exec_module
  File "<frozen importlib._bootstrap>", line 219, in _call_with_frames_removed
  File "/opt/airflow/dags/first_dag.py", line 2, in <module>
    from datetime import datetime, timedelat
ImportError: cannot import name 'timedelat' from 'datetime' (/usr/local/lib/python3.8/datetime.py)
[2023-12-21T19:59:58.954+0000] {processor.py:842} WARNING - No viable dags retrieved from /opt/airflow/dags/first_dag.py
[2023-12-21T19:59:58.982+0000] {processor.py:183} INFO - Processing /opt/airflow/dags/first_dag.py took 0.052 seconds
